Workbook

Sheet Übersicht Score Index
A1: CAS Nr. | B1: Rohstoff | C1: Unpleasant | D1: warm | E1: green | F1: floral | G1: citrus | H1: exotic | I1: Outlayer
A2: 0 | B2: 0 | C2: 0 - 10 | D2: 0 - 20 | E2: 0 | F2: 0 | G2: 0 | H2: 0 | I2: 0
A3: 14667-55-1 | B3: 2,3,5-Trimethylpyrazin, natürlich Halal | C3: 3 | D3: 3 | E3: 0 | F3: 0 | G3: 0 | H3: 0 | I3: 3
A4: 1192-62-7 | B4: 2-Acetylfuran, natürlich | C4: 0 | D4: 0 | E4: 0 | F4: 0 | G4: 0 | H4: 0 | I4: 0
A5: 15679-12-6 | B5: 2-Ethyl-4-methylthiazol, natürlich | C5: 0 | D5: 0 | E5: 0 | F5: 0 | G5: 0 | H5: 0 | I5: 0
A6: 110-43-0 | B6: 2-Heptanon Halal | C6: 0 | D6: 0 | E6: 0 | F6: 0 | G6: 0 | H6: 0 | I6: 0
A7: 137-32-6 | B7: 2-Methyl-1-butanol, natürlich Kosher Halal | C7: 0 | D7: 0 | E7: 0 | F7: 0 | G7: 0 | H7: 0 | I7: 0
A8: 3142-72-1 | B8: 2-Methyl-2-pentensäure | C8: 0 | D8: 0 | E8: 0 | F8: 0 | G8: 0 | H8: 0 | I8: 0
A9: 116-53-0 | B9: 2-Methylbuttersäure Halal Kosher | C9: 2 | D9: 2 | E9: 0 | F9: 0 | G9: 2 | H9: 2 | I9: 0
A10: 2445-78-5 | B10: 2-Methylbutyl-2-methylbutyrat | C10: 0 | D10: 0 | E10: 0 | F10: 0 | G10: 0 | H10: 0 | I10: 0
A11: 624-41-9 | B11: 2-Methylbutylacetat Kosher Halal | C11: 0 | D11: 0 | E11: 0 | F11: 0 | G11: 0 | H11: 0 | I11: 0
A12: 51115-64-1 | B12: 2-Methylbutylbutyrat | C12: 0 | D12: 0 | E12: 0 | F12: 0 | G12: 0 | H12: 0 | I12: 0
A13: 2445-77-4 | B13: 2-Methylbutylisovalerat | C13: 0 | D13: 0 | E13: 0 | F13: 0 | G13: 0 | H13: 0 | I13: 0
A14: 821-55-6 | B14: 2-Nonanon, natürlich Halal | C14: 0 | D14: 0 | E14: 0 | F14: 0 | G14: 0 | H14: 0 | I14: 0
... A79: 10191-41-0 | B79: DL-Alpha-Tocopherol Halal | C79: 0 | D79: 0 | E79: 0 | F79: 0 | G79: 0 | H79: 0 | I79: 0
B80: Erdbeer-Aroma Wasserphase Kosher, BG | C80: 0 | D80: 2 | E80: 2 | F80: 0 | G80: 0 | H80: 0 | I80: 2
A81: 64-19-7 | B81: Essigsäure Halal Kosher | C81: 2 | D81: 0 | E81: 0 | F81: 0 | G81: 2 | H81: 2 | I81: 0
A82: 7452-79-1 | B82: Ethyl-2-methylbutyrat Kosher Halal | C82: 0 | D82: 0 | E82: 2 | F82: 0 | G82: 0 | H82: 0 | I82: 0
A83: 141-78-6 | B83: Ethylacetat Kosher Halal | C83: 0 | D83: 0 | E83: 2 | F83: 0 | G83: 0 | H83: 0 | I83: 0
A84: 141-97-9 | B84: Ethylacetoacetat Halal | C84: 0 | D84: 0 | E84: 0 | F84: 0 | G84: 0 | H84: 0 | I84: 0
A85: 93-89-0 | B85: Ethylbenzoat | C85: 0 | D85: 0 | E85: 0 | F85: 0 | G85: 0 | H85: 0 | I85: 0
A86: 105-54-4 | B86: Ethylbutyrat Kosher Halal | C86: 0 | D86: 0 | E86: 2 | F86: 0 | G86: 0 | H86: 0 | I86: 0
A87: 103-36-6 | B87: Ethylcinnamat Halal | C87: 0 | D87: 0 | E87: 0 | F87: 0 | G87: 0 | H87: 0 | I87: 0
A88: 110-38-3 | B88: Ethyldecanoat Halal | C88: 0 | D88: 0 | E88: 0 | F88: 0 | G88: 0 | H88: 0 | I88: 0
A89: 109-94-4 | B89: Ethylformiat Halal | C89: 0 | D89: 0 | E89: 0 | F89: 0 | G89: 0 | H89: 0 | I89: 0
A90: 27538-09-6 | B90: Ethylfuraneol Kosher Halal | C90: 0 | D90: 0 | E90: 0 | F90: 0 | G90: 0 | H90: 0 | I90: 0
A91: 106-30-9 | B91: Ethylheptanoat | C91: 0 | D91: 0 | E91: 0 | F91: 0 | G91: 0 | H91: 0 | I91: 0
A92: 123-66-0 | B92: Ethylhexanoat Halal | C92: 0 | D92: 0 | E92: 3 | F92: 0 | G92: 0 | H92: 0 | I92: 0
... A227: 68917-33-9 | B227: Zitronenterpene Kosher Halal | C227: 0 | D227: 0 | E227: 0 | F227: 0 | G227: 5 | H227: 2 | I227: 0

Sheet Rezepte
A1: CAS Nr. | B1: Rohstoff | C1: Avg_Norm_When_Present Fred | D1: Avg_Norm_When_Present Meli | E1: 188.977 | F1: 188.977 | G1: 188.977 | I1: 185.267 | J1: 185.267 | K1: 185.267 | M1: 187.894 | Q1: 188.820 | U1: 188.412 | Y1: 187.829 | AC1: 185.237 | AG1: 185.294 | AK1: 187.776 | AP1: Summe(Rez) | AQ1: MW(Rez) | AR1: Med(Rez)
A2: 0 | B2: 0 | E2: Norm. Menge Rezept | F2: Dosage | G2: Norm. Menge Produkt | H2: Z-Score | I2: Norm. Menge Rezept | J2: Dosage | K2: Norm. Menge Produkt | L2: Z-Score | M2: Norm. Menge Rezept | N2: Dosage | O2: Norm. Menge Produkt | P2: Z-Score | Q2: Norm. Menge Rezept | R2: Dosage | S2: Norm. Menge Produkt | T2: Z-Score | U2: Norm. Menge Rezept | V2: Dosage | W2: Norm. Menge Produkt | X2: Z-Score | Y2: Norm. Menge Rezept | Z2: Dosage | AA2: Norm. Menge Produkt | AB2: Z-Score | AC2: Norm. Menge Rezept | AD2: Dosage | AE2: Norm. Menge Produkt | AF2: Z-Score | AG2: Norm. Menge Rezept | AH2: Dosage | AI2: Norm. Menge Produkt | AJ2: Z-Score | AK2: Norm. Menge Rezept | AL2: Dosage | AM2: Norm. Menge Produkt | AN2: Z-Score
A3: 14667-55-1 | B3: 2,3,5-Trimethylpyrazin, natürlich Halal | C3: 0.001746 | D3: 0.0017464503 | E3: 0.0017464503 | F3: 0.6 | G3: =+E3*$F$3 -> 0.0010478702 | H3: =+E3/D3 -> 1 | J3: 0.5 | K3: =I3*$J$3 -> 0 | L3: =+I3/D3 -> 0 | N3: 0.25 | O3: =+M3*$N$3 -> 0 | P3: =+M3/D3 -> 0 | R3: 0.3 | S3: =+Q3*$R$3 -> 0 | T3: =+Q3/D3 -> 0 | V3: 0.4 | W3: =+U3*$V$3 -> 0 | X3: =+U3/D3 -> 0 | Z3: 0.5 | AA3: =+Y3*$Z$3 -> 0 | AB3: =+Y3/D3 -> 0 | AD3: 0.5 | AE3: =+AC3*$AD$3 -> 0 | AF3: =+AC3/D3 -> 0 | AH3: 0.8 | AI3: =+AG3*$AH$3 -> 0 | AJ3: =+AG3/D3 -> 0 | AL3: 0.4 | AM3: =+AK3*$AL$3 -> 0 | AN3: =+AK3/D3 -> 0 | AP3: =SUM(E3,M3) -> 0.0017464503 | AQ3: =AVERAGE(G3,K3) -> 0.0005239351 | AR3: =MEDIAN(G3,K3) -> 0.0005239351
A4: 1192-62-7 | B4: 2-Acetylfuran, natürlich | C4: 0.002551 | D4: 0.0025524763 | G4: =+E4*$F$3 -> 0 | H4: =+E4/D4 -> 0 | K4: =I4*$J$3 -> 0 | L4: =+I4/D4 -> 0 | O4: =+M4*$N$3 -> 0 | P4: =+M4/D4 -> 0 | S4: =+Q4*$R$3 -> 0 | T4: =+Q4/D4 -> 0 | W4: =+U4*$V$3 -> 0 | X4: =+U4/D4 -> 0 | AA4: =+Y4*$Z$3 -> 0 | AB4: =+Y4/D4 -> 0 | AE4: =+AC4*$AD$3 -> 0 | AF4: =+AC4/D4 -> 0 | AI4: =+AG4*$AH$3 -> 0 | AJ4: =+AG4/D4 -> 0 | AM4: =+AK4*$AL$3 -> 0 | AN4: =+AK4/D4 -> 0 | AP4: =SUM(G4,K4) -> 0 | AQ4: =AVERAGE(G4,K4) -> 0 | AR4: =MEDIAN(G4,K4) -> 0
A5: 15679-12-6 | B5: 2-Ethyl-4-methylthiazol, natürlich | C5: 4e-06 | D5: 1.5966364e-05 | G5: =+E5*$F$3 -> 0 | H5: =+E5/D5 -> 0 | K5: =I5*$J$3 -> 0 | L5: =+I5/D5 -> 0 | O5: =+M5*$N$3 -> 0 | P5: =+M5/D5 -> 0 | S5: =+Q5*$R$3 -> 0 | T5: =+Q5/D5 -> 0 | W5: =+U5*$V$3 -> 0 | X5: =+U5/D5 -> 0 | AA5: =+Y5*$Z$3 -> 0 | AB5: =+Y5/D5 -> 0 | AE5: =+AC5*$AD$3 -> 0 | AF5: =+AC5/D5 -> 0 | AI5: =+AG5*$AH$3 -> 0 | AJ5: =+AG5/D5 -> 0 | AM5: =+AK5*$AL$3 -> 0 | AN5: =+AK5/D5 -> 0 | AP5: =SUM(G5,K5) -> 0 | AQ5: =AVERAGE(G5,K5) -> 0 | AR5: =MEDIAN(G5,K5) -> 0
A6: 110-43-0 | B6: 2-Heptanon Halal | C6: 0.002114 | D6: 0.005457918 | G6: =+E6*$F$3 -> 0 | H6: =+E6/D6 -> 0 | K6: =I6*$J$3 -> 0 | L6: =+I6/D6 -> 0 | O6: =+M6*$N$3 -> 0 | P6: =+M6/D6 -> 0 | S6: =+Q6*$R$3 -> 0 | T6: =+Q6/D6 -> 0 | W6: =+U6*$V$3 -> 0 | X6: =+U6/D6 -> 0 | AA6: =+Y6*$Z$3 -> 0 | AB6: =+Y6/D6 -> 0 | AE6: =+AC6*$AD$3 -> 0 | AF6: =+AC6/D6 -> 0 | AI6: =+AG6*$AH$3 -> 0 | AJ6: =+AG6/D6 -> 0 | AM6: =+AK6*$AL$3 -> 0 | AN6: =+AK6/D6 -> 0 | AP6: =SUM(G6,K6) -> 0 | AQ6: =AVERAGE(G6,K6) -> 0 | AR6: =MEDIAN(G6,K6) -> 0
A7: 137-32-6 | B7: 2-Methyl-1-butanol, natürlich Kosher Halal | C7: 0.001757 | D7: 0.010954855 | G7: =+E7*$F$3 -> 0 | H7: =+E7/D7 -> 0 | K7: =I7*$J$3 -> 0 | L7: =+I7/D7 -> 0 | O7: =+M7*$N$3 -> 0 | P7: =+M7/D7 -> 0 | S7: =+Q7*$R$3 -> 0 | T7: =+Q7/D7 -> 0 | W7: =+U7*$V$3 -> 0 | X7: =+U7/D7 -> 0 | AA7: =+Y7*$Z$3 -> 0 | AB7: =+Y7/D7 -> 0 | AE7: =+AC7*$AD$3 -> 0 | AF7: =+AC7/D7 -> 0 | AI7: =+AG7*$AH$3 -> 0 | AJ7: =+AG7/D7 -> 0 | AM7: =+AK7*$AL$3 -> 0 | AN7: =+AK7/D7 -> 0 | AP7: =SUM(G7,K7) -> 0 | AQ7: =AVERAGE(G7,K7) -> 0 | AR7: =MEDIAN(G7,K7) -> 0
A8: 3142-72-1 | B8: 2-Methyl-2-pentensäure | C8: 0.005825 | D8: 0.0080171916 | E8: 0.0023286005 | G8: =+E8*$F$3 -> 0.0013971603 | H8: =+E8/D8 -> 0.29045089 | K8: =I8*$J$3 -> 0 | L8: =+I8/D8 -> 0 | O8: =+M8*$N$3 -> 0 | P8: =+M8/D8 -> 0 | S8: =+Q8*$R$3 -> 0 | T8: =+Q8/D8 -> 0 | W8: =+U8*$V$3 -> 0 | X8: =+U8/D8 -> 0 | AA8: =+Y8*$Z$3 -> 0 | AB8: =+Y8/D8 -> 0 | AE8: =+AC8*$AD$3 -> 0 | AF8: =+AC8/D8 -> 0 | AI8: =+AG8*$AH$3 -> 0 | AJ8: =+AG8/D8 -> 0 | AM8: =+AK8*$AL$3 -> 0 | AN8: =+AK8/D8 -> 0 | AP8: =SUM(G8,K8) -> 0.0013971603 | AQ8: =AVERAGE(G8,K8) -> 0.00069858014 | AR8: =MEDIAN(G8,K8) -> 0.00069858014
A9: 116-53-0 | B9: 2-Methylbuttersäure Halal Kosher | C9: 0.063624 | D9: 0.075563403 | E9: 0.081501016 | G9: =+E9*$F$3 -> 0.04890061 | H9: =+E9/D9 -> 1.0785779 | I9: 0.26470455 | K9: =I9*$J$3 -> 0.13235227 | L9: =+I9/D9 -> 3.5030787 | M9: 0.059889355 | O9: =+M9*$N$3 -> 0.014972339 | P9: =+M9/D9 -> 0.79257091 | Q9: 0.095326965 | S9: =+Q9*$R$3 -> 0.028598089 | T9: =+Q9/D9 -> 1.2615494 | U9: 0.14685356 | W9: =+U9*$V$3 -> 0.058741422 | X9: =+U9/D9 -> 1.9434482 | Y9: 0.21127333 | AA9: =+Y9*$Z$3 -> 0.10563667 | AB9: =+Y9/D9 -> 2.7959743 | AC9: 0.16354882 | AE9: =+AC9*$AD$3 -> 0.081774408 | AF9: =+AC9/D9 -> 2.1643919 | AG9: 0.068143231 | AI9: =+AG9*$AH$3 -> 0.054514585 | AJ9: =+AG9/D9 -> 0.90180203 | AK9: 0.057998393 | AM9: =+AK9*$AL$3 -> 0.023199357 | AN9: =+AK9/D9 -> 0.76754607 | AP9: =SUM(G9,K9) -> 0.18125288 | AQ9: =AVERAGE(G9,K9) -> 0.090626441 | AR9: =MEDIAN(G9,K9) -> 0.090626441
A10: 2445-78-5 | B10: 2-Methylbutyl-2-methylbutyrat | C10: 0.000186 | D10: 0.00018632901 | G10: =+E10*$F$3 -> 0 | H10: =+E10/D10 -> 0 | K10: =I10*$J$3 -> 0 | L10: =+I10/D10 -> 0 | O10: =+M10*$N$3 -> 0 | P10: =+M10/D10 -> 0 | S10: =+Q10*$R$3 -> 0 | T10: =+Q10/D10 -> 0 | W10: =+U10*$V$3 -> 0 | X10: =+U10/D10 -> 0 | AA10: =+Y10*$Z$3 -> 0 | AB10: =+Y10/D10 -> 0 | AE10: =+AC10*$AD$3 -> 0 | AF10: =+AC10/D10 -> 0 | AI10: =+AG10*$AH$3 -> 0 | AJ10: =+AG10/D10 -> 0 | AM10: =+AK10*$AL$3 -> 0 | AN10: =+AK10/D10 -> 0 | AP10: =SUM(G10,K10) -> 0 | AQ10: =AVERAGE(G10,K10) -> 0 | AR10: =MEDIAN(G10,K10) -> 0
A11: 624-41-9 | B11: 2-Methylbutylacetat Kosher Halal | C11: 0.001025 | D11: 0.0016621992 | G11: =+E11*$F$3 -> 0 | H11: =+E11/D11 -> 0 | K11: =I11*$J$3 -> 0 | L11: =+I11/D11 -> 0 | O11: =+M11*$N$3 -> 0 | P11: =+M11/D11 -> 0 | S11: =+Q11*$R$3 -> 0 | T11: =+Q11/D11 -> 0 | W11: =+U11*$V$3 -> 0 | X11: =+U11/D11 -> 0 | AA11: =+Y11*$Z$3 -> 0 | AB11: =+Y11/D11 -> 0 | AE11: =+AC11*$AD$3 -> 0 | AF11: =+AC11/D11 -> 0 | AI11: =+AG11*$AH$3 -> 0 | AJ11: =+AG11/D11 -> 0 | AM11: =+AK11*$AL$3 -> 0 | AN11: =+AK11/D11 -> 0 | AP11: =SUM(G11,K11) -> 0 | AQ11: =AVERAGE(G11,K11) -> 0 | AR11: =MEDIAN(G11,K11) -> 0
A12: 51115-64-1 | B12: 2-Methylbutylbutyrat | C12: 0.003767 | D12: 0.0033964943 | G12: =+E12*$F$3 -> 0 | H12: =+E12/D12 -> 0 | K12: =I12*$J$3 -> 0 | L12: =+I12/D12 -> 0 | M12: 0.00069988728 | O12: =+M12*$N$3 -> 0.00017497182 | P12: =+M12/D12 -> 0.20606167 | S12: =+Q12*$R$3 -> 0 | T12: =+Q12/D12 -> 0 | W12: =+U12*$V$3 -> 0 | X12: =+U12/D12 -> 0 | AA12: =+Y12*$Z$3 -> 0 | AB12: =+Y12/D12 -> 0 | AE12: =+AC12*$AD$3 -> 0 | AF12: =+AC12/D12 -> 0 | AI12: =+AG12*$AH$3 -> 0 | AJ12: =+AG12/D12 -> 0 | AM12: =+AK12*$AL$3 -> 0 | AN12: =+AK12/D12 -> 0 | AP12: =SUM(G12,K12) -> 0 | AQ12: =AVERAGE(G12,K12) -> 0 | AR12: =MEDIAN(G12,K12) -> 0
A13: 2445-77-4 | B13: 2-Methylbutylisovalerat | C13: 0.003091 | D13: 0.0031574925 | G13: =+E13*$F$3 -> 0 | H13: =+E13/D13 -> 0 | K13: =I13*$J$3 -> 0 | L13: =+I13/D13 -> 0 | O13: =+M13*$N$3 -> 0 | P13: =+M13/D13 -> 0 | S13: =+Q13*$R$3 -> 0 | T13: =+Q13/D13 -> 0 | W13: =+U13*$V$3 -> 0 | X13: =+U13/D13 -> 0 | AA13: =+Y13*$Z$3 -> 0 | AB13: =+Y13/D13 -> 0 | AE13: =+AC13*$AD$3 -> 0 | AF13: =+AC13/D13 -> 0 | AI13: =+AG13*$AH$3 -> 0 | AJ13: =+AG13/D13 -> 0 | AM13: =+AK13*$AL$3 -> 0 | AN13: =+AK13/D13 -> 0 | AP13: =SUM(G13,K13) -> 0 | AQ13: =AVERAGE(G13,K13) -> 0 | AR13: =MEDIAN(G13,K13) -> 0
A14: 821-55-6 | B14: 2-Nonanon, natürlich Halal | C14: 0.000113 | D14: 0.00013954669 | G14: =+E14*$F$3 -> 0 | H14: =+E14/D14 -> 0 | K14: =I14*$J$3 -> 0 | L14: =+I14/D14 -> 0 | O14: =+M14*$N$3 -> 0 | P14: =+M14/D14 -> 0 | S14: =+Q14*$R$3 -> 0 | T14: =+Q14/D14 -> 0 | W14: =+U14*$V$3 -> 0 | X14: =+U14/D14 -> 0 | AA14: =+Y14*$Z$3 -> 0 | AB14: =+Y14/D14 -> 0 | AE14: =+AC14*$AD$3 -> 0 | AF14: =+AC14/D14 -> 0 | AI14: =+AG14*$AH$3 -> 0 | AJ14: =+AG14/D14 -> 0 | AM14: =+AK14*$AL$3 -> 0 | AN14: =+AK14/D14 -> 0 | AP14: =SUM(G14,K14) -> 0 | AQ14: =AVERAGE(G14,K14) -> 0 | AR14: =MEDIAN(G14,K14) -> 0
A15: 111-13-7 | B15: 2-Octanon Halal | C15: 0.001896 | D15: 0.0048223366 | G15: =+E15*$F$3 -> 0 | H15: =+E15/D15 -> 0 | K15: =I15*$J$3 -> 0 | L15: =+I15/D15 -> 0 | O15: =+M15*$N$3 -> 0 | P15: =+M15/D15 -> 0 | S15: =+Q15*$R$3 -> 0 | T15: =+Q15/D15 -> 0 | W15: =+U15*$V$3 -> 0 | X15: =+U15/D15 -> 0 | AA15: =+Y15*$Z$3 -> 0 | AB15: =+Y15/D15 -> 0 | AE15: =+AC15*$AD$3 -> 0 | AF15: =+AC15/D15 -> 0 | AI15: =+AG15*$AH$3 -> 0 | AJ15: =+AG15/D15 -> 0 | AM15: =+AK15*$AL$3 -> 0 | AN15: =+AK15/D15 -> 0 | AP15: =SUM(G15,K15) -> 0 | AQ15: =AVERAGE(G15,K15) -> 0 | AR15: =MEDIAN(G15,K15) -> 0
A16: 4643-27-0 | B16: 2-Octen-4-on | C16: 0.00114 | D16: 0.0011403701 | G16: =+E16*$F$3 -> 0 | H16: =+E16/D16 -> 0 | K16: =I16*$J$3 -> 0 | L16: =+I16/D16 -> 0 | O16: =+M16*$N$3 -> 0 | P16: =+M16/D16 -> 0 | S16: =+Q16*$R$3 -> 0 | T16: =+Q16/D16 -> 0 | W16: =+U16*$V$3 -> 0 | X16: =+U16/D16 -> 0 | AA16: =+Y16*$Z$3 -> 0 | AB16: =+Y16/D16 -> 0 | AE16: =+AC16*$AD$3 -> 0 | AF16: =+AC16/D16 -> 0 | AI16: =+AG16*$AH$3 -> 0 | AJ16: =+AG16/D16 -> 0 | AM16: =+AK16*$AL$3 -> 0 | AN16: =+AK16/D16 -> 0 | AP16: =SUM(G16,K16) -> 0 | AQ16: =AVERAGE(G16,K16) -> 0 | AR16: =MEDIAN(G16,K16) -> 0
A17: 107-87-9 | B17: 2-Pentanon, natürlich Halal | C17: 0.000576 | D17: 0.00075018613 | G17: =+E17*$F$3 -> 0 | H17: =+E17/D17 -> 0 | K17: =I17*$J$3 -> 0 | L17: =+I17/D17 -> 0 | O17: =+M17*$N$3 -> 0 | P17: =+M17/D17 -> 0 | S17: =+Q17*$R$3 -> 0 | T17: =+Q17/D17 -> 0 | W17: =+U17*$V$3 -> 0 | X17: =+U17/D17 -> 0 | AA17: =+Y17*$Z$3 -> 0 | AB17: =+Y17/D17 -> 0 | AE17: =+AC17*$AD$3 -> 0 | AF17: =+AC17/D17 -> 0 | AI17: =+AG17*$AH$3 -> 0 | AJ17: =+AG17/D17 -> 0 | AM17: =+AK17*$AL$3 -> 0 | AN17: =+AK17/D17 -> 0 | AP17: =SUM(G17,K17) -> 0 | AQ17: =AVERAGE(G17,K17) -> 0 | AR17: =MEDIAN(G17,K17) -> 0
A18: 112-12-9 | B18: 2-Undecanon, natürlich Halal | C18: 0.000103 | D18: 0.0001326206 | G18: =+E18*$F$3 -> 0 | H18: =+E18/D18 -> 0 | K18: =I18*$J$3 -> 0 | L18: =+I18/D18 -> 0 | O18: =+M18*$N$3 -> 0 | P18: =+M18/D18 -> 0 | S18: =+Q18*$R$3 -> 0 | T18: =+Q18/D18 -> 0 | W18: =+U18*$V$3 -> 0 | X18: =+U18/D18 -> 0 | AA18: =+Y18*$Z$3 -> 0 | AB18: =+Y18/D18 -> 0 | AE18: =+AC18*$AD$3 -> 0 | AF18: =+AC18/D18 -> 0 | AI18: =+AG18*$AH$3 -> 0 | AJ18: =+AG18/D18 -> 0 | AM18: =+AK18*$AL$3 -> 0 | AN18: =+AK18/D18 -> 0 | AP18: =SUM(G18,K18) -> 0 | AQ18: =AVERAGE(G18,K18) -> 0 | AR18: =MEDIAN(G18,K18) -> 0
A19: 7786-61-0 | B19: 4-Vinylguajacol 1% in PG, natürlich | C19: 7e-05 | D19: 6.9843441e-05 | G19: =+E19*$F$3 -> 0 | H19: =+E19/D19 -> 0 | K19: =I19*$J$3 -> 0 | L19: =+I19/D19 -> 0 | O19: =+M19*$N$3 -> 0 | P19: =+M19/D19 -> 0 | S19: =+Q19*$R$3 -> 0 | T19: =+Q19/D19 -> 0 | W19: =+U19*$V$3 -> 0 | X19: =+U19/D19 -> 0 | AA19: =+Y19*$Z$3 -> 0 | AB19: =+Y19/D19 -> 0 | AE19: =+AC19*$AD$3 -> 0 | AF19: =+AC19/D19 -> 0 | AI19: =+AG19*$AH$3 -> 0 | AJ19: =+AG19/D19 -> 0 | AM19: =+AK19*$AL$3 -> 0 | AN19: =+AK19/D19 -> 0 | AP19: =SUM(G19,K19) -> 0 | AQ19: =AVERAGE(G19,K19) -> 0 | AR19: =MEDIAN(G19,K19) -> 0
A20: 105-57-7 | B20: Acetal Halal | C20: 0.00121 | D20: 0.0038671442 | G20: =+E20*$F$3 -> 0 | H20: =+E20/D20 -> 0 | K20: =I20*$J$3 -> 0 | L20: =+I20/D20 -> 0 | M20: 0.0019946788 | O20: =+M20*$N$3 -> 0.00049866969 | P20: =+M20/D20 -> 0.51580149 | S20: =+Q20*$R$3 -> 0 | T20: =+Q20/D20 -> 0 | W20: =+U20*$V$3 -> 0 | X20: =+U20/D20 -> 0 | AA20: =+Y20*$Z$3 -> 0 | AB20: =+Y20/D20 -> 0 | AE20: =+AC20*$AD$3 -> 0 | AF20: =+AC20/D20 -> 0 | AI20: =+AG20*$AH$3 -> 0 | AJ20: =+AG20/D20 -> 0 | AM20: =+AK20*$AL$3 -> 0 | AN20: =+AK20/D20 -> 0 | AP20: =SUM(G20,K20) -> 0 | AQ20: =AVERAGE(G20,K20) -> 0 | AR20: =MEDIAN(G20,K20) -> 0
A21: 75-07-0 | B21: Acetaldehyd Halal Kosher | C21: 0.006845 | D21: 0.0072243473 | G21: =+E21*$F$3 -> 0 | H21: =+E21/D21 -> 0 | K21: =I21*$J$3 -> 0 | L21: =+I21/D21 -> 0 | O21: =+M21*$N$3 -> 0 | P21: =+M21/D21 -> 0 | Q21: 0.00067131665 | S21: =+Q21*$R$3 -> 0.000201395 | T21: =+Q21/D21 -> 0.092924194 | W21: =+U21*$V$3 -> 0 | X21: =+U21/D21 -> 0 | AA21: =+Y21*$Z$3 -> 0 | AB21: =+Y21/D21 -> 0 | AE21: =+AC21*$AD$3 -> 0 | AF21: =+AC21/D21 -> 0 | AG21: 0.0053057829 | AI21: =+AG21*$AH$3 -> 0.0042446263 | AJ21: =+AG21/D21 -> 0.73443076 | AM21: =+AK21*$AL$3 -> 0 | AN21: =+AK21/D21 -> 0 | AP21: =SUM(G21,K21) -> 0 | AQ21: =AVERAGE(G21,K21) -> 0 | AR21: =MEDIAN(G21,K21) -> 0
A22: 3390-12-3 | B22: Acetaldehyd PG acetal | C22: 0.007211 | D22: 0.0072058862 | G22: =+E22*$F$3 -> 0 | H22: =+E22/D22 -> 0 | K22: =I22*$J$3 -> 0 | L22: =+I22/D22 -> 0 | O22: =+M22*$N$3 -> 0 | P22: =+M22/D22 -> 0 | S22: =+Q22*$R$3 -> 0 | T22: =+Q22/D22 -> 0 | W22: =+U22*$V$3 -> 0 | X22: =+U22/D22 -> 0 | AA22: =+Y22*$Z$3 -> 0 | AB22: =+Y22/D22 -> 0 | AE22: =+AC22*$AD$3 -> 0 | AF22: =+AC22/D22 -> 0 | AI22: =+AG22*$AH$3 -> 0 | AJ22: =+AG22/D22 -> 0 | AM22: =+AK22*$AL$3 -> 0 | AN22: =+AK22/D22 -> 0 | AP22: =SUM(G22,K22) -> 0 | AQ22: =AVERAGE(G22,K22) -> 0 | AR22: =MEDIAN(G22,K22) -> 0
A23: 513-86-0 | B23: Acetoin, natürlich Kosher Halal PUR umgerechnet!!! | C23: 0.040827 | D23: 0.016429707 | H23: =+E23/D23 -> 0 | L23: =+I23/D23 -> 0 | P23: =+M23/D23 -> 0 | S23: =+Q23*$R$3 -> 0 | T23: =+Q23/D23 -> 0 | W23: =+U23*$V$3 -> 0 | X23: =+U23/D23 -> 0 | AA23: =+Y23*$Z$3 -> 0 | AB23: =+Y23/D23 -> 0 | AE23: =+AC23*$AD$3 -> 0 | AF23: =+AC23/D23 -> 0 | AG23: 0.002666 | AI23: =+AG23*$AH$3 -> 0.0021328 | AJ23: =+AG23/D23 -> 0.16226705 | AM23: =+AK23*$AL$3 -> 0 | AN23: =+AK23/D23 -> 0
A24: 67-64-1 | B24: Aceton | C24: 0.000885 | D24: 0.00088462408 | G24: =+E24*$F$3 -> 0 | H24: =+E24/D24 -> 0 | K24: =I24*$J$3 -> 0 | L24: =+I24/D24 -> 0 | O24: =+M24*$N$3 -> 0 | P24: =+M24/D24 -> 0 | S24: =+Q24*$R$3 -> 0 | T24: =+Q24/D24 -> 0 | W24: =+U24*$V$3 -> 0 | X24: =+U24/D24 -> 0 | AA24: =+Y24*$Z$3 -> 0 | AB24: =+Y24/D24 -> 0 | AE24: =+AC24*$AD$3 -> 0 | AF24: =+AC24/D24 -> 0 | AI24: =+AG24*$AH$3 -> 0 | AJ24: =+AG24/D24 -> 0 | AM24: =+AK24*$AL$3 -> 0 | AN24: =+AK24/D24 -> 0 | AP24: =SUM(G24,K24) -> 0 | AQ24: =AVERAGE(G24,K24) -> 0 | AR24: =MEDIAN(G24,K24) -> 0
A25: 98-86-2 | B25: Acetophenon, natürlich Halal | C25: 0.000534 | D25: 0.00099664938 | G25: =+E25*$F$3 -> 0 | H25: =+E25/D25 -> 0 | K25: =I25*$J$3 -> 0 | L25: =+I25/D25 -> 0 | O25: =+M25*$N$3 -> 0 | P25: =+M25/D25 -> 0 | S25: =+Q25*$R$3 -> 0 | T25: =+Q25/D25 -> 0 | W25: =+U25*$V$3 -> 0 | X25: =+U25/D25 -> 0 | AA25: =+Y25*$Z$3 -> 0 | AB25: =+Y25/D25 -> 0 | AE25: =+AC25*$AD$3 -> 0 | AF25: =+AC25/D25 -> 0 | AI25: =+AG25*$AH$3 -> 0 | AJ25: =+AG25/D25 -> 0 | AM25: =+AK25*$AL$3 -> 0 | AN25: =+AK25/D25 -> 0 | AP25: =SUM(G25,K25) -> 0 | AQ25: =AVERAGE(G25,K25) -> 0 | AR25: =MEDIAN(G25,K25) -> 0
A26: 2719-08-6 | B26: Acetyl N-methylanthranilat | C26: 0.001344 | D26: 0.0011139492 | G26: =+E26*$F$3 -> 0 | H26: =+E26/D26 -> 0 | K26: =I26*$J$3 -> 0 | L26: =+I26/D26 -> 0 | O26: =+M26*$N$3 -> 0 | P26: =+M26/D26 -> 0 | S26: =+Q26*$R$3 -> 0 | T26: =+Q26/D26 -> 0 | W26: =+U26*$V$3 -> 0 | X26: =+U26/D26 -> 0 | AA26: =+Y26*$Z$3 -> 0 | AB26: =+Y26/D26 -> 0 | AE26: =+AC26*$AD$3 -> 0 | AF26: =+AC26/D26 -> 0 | AI26: =+AG26*$AH$3 -> 0 | AJ26: =+AG26/D26 -> 0 | AM26: =+AK26*$AL$3 -> 0 | AN26: =+AK26/D26 -> 0 | AP26: =SUM(G26,K26) -> 0 | AQ26: =AVERAGE(G26,K26) -> 0 | AR26: =MEDIAN(G26,K26) -> 0
A27: 600-14-6 | B27: Acetylpropionyl Halal | C27: 0.01055 | D27: 0.014565697 | G27: =+E27*$F$3 -> 0 | H27: =+E27/D27 -> 0 | K27: =I27*$J$3 -> 0 | L27: =+I27/D27 -> 0 | M27: 0.0038143857 | O27: =+M27*$N$3 -> 0.00095359642 | P27: =+M27/D27 -> 0.26187457 | S27: =+Q27*$R$3 -> 0 | T27: =+Q27/D27 -> 0 | W27: =+U27*$V$3 -> 0 | X27: =+U27/D27 -> 0 | AA27: =+Y27*$Z$3 -> 0 | AB27: =+Y27/D27 -> 0 | AE27: =+AC27*$AD$3 -> 0 | AF27: =+AC27/D27 -> 0 | AI27: =+AG27*$AH$3 -> 0 | AJ27: =+AG27/D27 -> 0 | AM27: =+AK27*$AL$3 -> 0 | AN27: =+AK27/D27 -> 0 | AP27: =SUM(G27,K27) -> 0 | AQ27: =AVERAGE(G27,K27) -> 0 | AR27: =MEDIAN(G27,K27) -> 0
A28: 123-68-2 | B28: Allylhexanoat, natürlich Halal | C28: 0.000312 | D28: 0.00031244065 | G28: =+E28*$F$3 -> 0 | H28: =+E28/D28 -> 0 | K28: =I28*$J$3 -> 0 | L28: =+I28/D28 -> 0 | O28: =+M28*$N$3 -> 0 | P28: =+M28/D28 -> 0 | S28: =+Q28*$R$3 -> 0 | T28: =+Q28/D28 -> 0 | W28: =+U28*$V$3 -> 0 | X28: =+U28/D28 -> 0 | AA28: =+Y28*$Z$3 -> 0 | AB28: =+Y28/D28 -> 0 | AE28: =+AC28*$AD$3 -> 0 | AF28: =+AC28/D28 -> 0 | AI28: =+AG28*$AH$3 -> 0 | AJ28: =+AG28/D28 -> 0 | AM28: =+AK28*$AL$3 -> 0 | AN28: =+AK28/D28 -> 0 | AP28: =SUM(G28,K28) -> 0 | AQ28: =AVERAGE(G28,K28) -> 0 | AR28: =MEDIAN(G28,K28) -> 0
A29: 127-41-3 | B29: alpha-Ionon Halal Kosher | C29: 0.002592 | D29: 0.0025923091 | G29: =+E29*$F$3 -> 0 | H29: =+E29/D29 -> 0 | K29: =I29*$J$3 -> 0 | L29: =+I29/D29 -> 0 | O29: =+M29*$N$3 -> 0 | P29: =+M29/D29 -> 0 | S29: =+Q29*$R$3 -> 0 | T29: =+Q29/D29 -> 0 | W29: =+U29*$V$3 -> 0 | X29: =+U29/D29 -> 0 | AA29: =+Y29*$Z$3 -> 0 | AB29: =+Y29/D29 -> 0 | AE29: =+AC29*$AD$3 -> 0 | AF29: =+AC29/D29 -> 0 | AI29: =+AG29*$AH$3 -> 0 | AJ29: =+AG29/D29 -> 0 | AM29: =+AK29*$AL$3 -> 0 | AN29: =+AK29/D29 -> 0 | AP29: =SUM(G29,K29) -> 0 | AQ29: =AVERAGE(G29,K29) -> 0 | AR29: =MEDIAN(G29,K29) -> 0
A30: 79-69-6 | B30: alpha-Iron | C30: 0.000303 | D30: 0.00030298469 | G30: =+E30*$F$3 -> 0 | H30: =+E30/D30 -> 0 | K30: =I30*$J$3 -> 0 | L30: =+I30/D30 -> 0 | O30: =+M30*$N$3 -> 0 | P30: =+M30/D30 -> 0 | S30: =+Q30*$R$3 -> 0 | T30: =+Q30/D30 -> 0 | W30: =+U30*$V$3 -> 0 | X30: =+U30/D30 -> 0 | AA30: =+Y30*$Z$3 -> 0 | AB30: =+Y30/D30 -> 0 | AE30: =+AC30*$AD$3 -> 0 | AF30: =+AC30/D30 -> 0 | AI30: =+AG30*$AH$3 -> 0 | AJ30: =+AG30/D30 -> 0 | AM30: =+AK30*$AL$3 -> 0 | AN30: =+AK30/D30 -> 0 | AP30: =SUM(G30,K30) -> 0 | AQ30: =AVERAGE(G30,K30) -> 0 | AR30: =MEDIAN(G30,K30) -> 0
A31: 98-55-5 | B31: alpha-Terpineol Kosher Halal | C31: 0.016242 | D31: 0.016830004 | G31: =+E31*$F$3 -> 0 | H31: =+E31/D31 -> 0 | K31: =I31*$J$3 -> 0 | L31: =+I31/D31 -> 0 | O31: =+M31*$N$3 -> 0 | P31: =+M31/D31 -> 0 | S31: =+Q31*$R$3 -> 0 | T31: =+Q31/D31 -> 0 | W31: =+U31*$V$3 -> 0 | X31: =+U31/D31 -> 0 | AA31: =+Y31*$Z$3 -> 0 | AB31: =+Y31/D31 -> 0 | AE31: =+AC31*$AD$3 -> 0 | AF31: =+AC31/D31 -> 0 | AI31: =+AG31*$AH$3 -> 0 | AJ31: =+AG31/D31 -> 0 | AM31: =+AK31*$AL$3 -> 0 | AN31: =+AK31/D31 -> 0 | AP31: =SUM(G31,K31) -> 0 | AQ31: =AVERAGE(G31,K31) -> 0 | AR31: =MEDIAN(G31,K31) -> 0
A32: 64-18-6 | B32: Ameisensäure 80%, natürlich Kosher, Halal | C32: 0.000538 | D32: 0.008404065 | E32: 0.00024450305 | G32: =+E32*$F$3 -> 0.00014670183 | H32: =+E32/D32 -> 0.029093426 | K32: =I32*$J$3 -> 0 | L32: =+I32/D32 -> 0 | O32: =+M32*$N$3 -> 0 | P32: =+M32/D32 -> 0 | Q32: 6.7131665e-06 | S32: =+Q32*$R$3 -> 2.01395e-06 | T32: =+Q32/D32 -> 0.00079879993 | W32: =+U32*$V$3 -> 0 | X32: =+U32/D32 -> 0 | AA32: =+Y32*$Z$3 -> 0 | AB32: =+Y32/D32 -> 0 | AC32: 0.0058864388 | AE32: =+AC32*$AD$3 -> 0.0029432194 | AF32: =+AC32/D32 -> 0.70042757 | AI32: =+AG32*$AH$3 -> 0 | AJ32: =+AG32/D32 -> 0 | AK32: 8.648095e-06 | AM32: =+AK32*$AL$3 -> 3.459238e-06 | AN32: =+AK32/D32 -> 0.0010290371 | AP32: =SUM(G32,K32) -> 0.00014670183 | AQ32: =AVERAGE(G32,K32) -> 7.3350914e-05 | AR32: =MEDIAN(G32,K32) -> 7.3350914e-05
A33: 540-18-1 | B33: Amylbutyrat | C33: 0.015147 | D33: 0.015147394 | G33: =+E33*$F$3 -> 0 | H33: =+E33/D33 -> 0 | K33: =I33*$J$3 -> 0 | L33: =+I33/D33 -> 0 | O33: =+M33*$N$3 -> 0 | P33: =+M33/D33 -> 0 | S33: =+Q33*$R$3 -> 0 | T33: =+Q33/D33 -> 0 | W33: =+U33*$V$3 -> 0 | X33: =+U33/D33 -> 0 | AA33: =+Y33*$Z$3 -> 0 | AB33: =+Y33/D33 -> 0 | AE33: =+AC33*$AD$3 -> 0 | AF33: =+AC33/D33 -> 0 | AI33: =+AG33*$AH$3 -> 0 | AJ33: =+AG33/D33 -> 0 | AM33: =+AK33*$AL$3 -> 0 | AN33: =+AK33/D33 -> 0 | AP33: =SUM(G33,K33) -> 0 | AQ33: =AVERAGE(G33,K33) -> 0 | AR33: =MEDIAN(G33,K33) -> 0
A34: 123-11-5 | B34: Anisaldehyd Halal | C34: 0.005509 | D34: 0.0055091749 | G34: =+E34*$F$3 -> 0 | H34: =+E34/D34 -> 0 | K34: =I34*$J$3 -> 0 | L34: =+I34/D34 -> 0 | O34: =+M34*$N$3 -> 0 | P34: =+M34/D34 -> 0 | S34: =+Q34*$R$3 -> 0 | T34: =+Q34/D34 -> 0 | W34: =+U34*$V$3 -> 0 | X34: =+U34/D34 -> 0 | AA34: =+Y34*$Z$3 -> 0 | AB34: =+Y34/D34 -> 0 | AE34: =+AC34*$AD$3 -> 0 | AF34: =+AC34/D34 -> 0 | AI34: =+AG34*$AH$3 -> 0 | AJ34: =+AG34/D34 -> 0 | AM34: =+AK34*$AL$3 -> 0 | AN34: =+AK34/D34 -> 0 | AP34: =SUM(G34,K34) -> 0 | AQ34: =AVERAGE(G34,K34) -> 0 | AR34: =MEDIAN(G34,K34) -> 0
A35: 104-21-2 | B35: Anisylacetat Halal | C35: 0.00109 | D35: 0.0014223424 | G35: =+E35*$F$3 -> 0 | H35: =+E35/D35 -> 0 | K35: =I35*$J$3 -> 0 | L35: =+I35/D35 -> 0 | O35: =+M35*$N$3 -> 0 | P35: =+M35/D35 -> 0 | S35: =+Q35*$R$3 -> 0 | T35: =+Q35/D35 -> 0 | W35: =+U35*$V$3 -> 0 | X35: =+U35/D35 -> 0 | AA35: =+Y35*$Z$3 -> 0 | AB35: =+Y35/D35 -> 0 | AE35: =+AC35*$AD$3 -> 0 | AF35: =+AC35/D35 -> 0 | AI35: =+AG35*$AH$3 -> 0 | AJ35: =+AG35/D35 -> 0 | AM35: =+AK35*$AL$3 -> 0 | AN35: =+AK35/D35 -> 0 | AP35: =SUM(G35,K35) -> 0 | AQ35: =AVERAGE(G35,K35) -> 0 | AR35: =MEDIAN(G35,K35) -> 0
A36: 100-52-7 | B36: Benzaldehyd Kosher Halal | C36: 0.001532 | D36: 0.0020064464 | G36: =+E36*$F$3 -> 0 | H36: =+E36/D36 -> 0 | K36: =I36*$J$3 -> 0 | L36: =+I36/D36 -> 0 | O36: =+M36*$N$3 -> 0 | P36: =+M36/D36 -> 0 | S36: =+Q36*$R$3 -> 0 | T36: =+Q36/D36 -> 0 | U36: 0.00064377368 | W36: =+U36*$V$3 -> 0.00025750947 | X36: =+U36/D36 -> 0.32085267 | AA36: =+Y36*$Z$3 -> 0 | AB36: =+Y36/D36 -> 0 | AE36: =+AC36*$AD$3 -> 0 | AF36: =+AC36/D36 -> 0 | AI36: =+AG36*$AH$3 -> 0 | AJ36: =+AG36/D36 -> 0 | AK36: 0.0022675979 | AM36: =+AK36*$AL$3 -> 0.00090703916 | AN36: =+AK36/D36 -> 1.1301562 | AP36: =SUM(G36,K36) -> 0 | AQ36: =AVERAGE(G36,K36) -> 0 | AR36: =MEDIAN(G36,K36) -> 0
A37: 140-11-4 | B37: Benzylacetat Halal | C37: 0.004795 | D37: 0.0069628288 | G37: =+E37*$F$3 -> 0 | H37: =+E37/D37 -> 0 | K37: =I37*$J$3 -> 0 | L37: =+I37/D37 -> 0 | O37: =+M37*$N$3 -> 0 | P37: =+M37/D37 -> 0 | S37: =+Q37*$R$3 -> 0 | T37: =+Q37/D37 -> 0 | U37: 0.00096566053 | W37: =+U37*$V$3 -> 0.00038626421 | X37: =+U37/D37 -> 0.13868796 | AA37: =+Y37*$Z$3 -> 0 | AB37: =+Y37/D37 -> 0 | AE37: =+AC37*$AD$3 -> 0 | AF37: =+AC37/D37 -> 0 | AI37: =+AG37*$AH$3 -> 0 | AJ37: =+AG37/D37 -> 0 | AK37: 0.020643115 | AM37: =+AK37*$AL$3 -> 0.008257246 | AN37: =+AK37/D37 -> 2.9647598 | AP37: =SUM(G37,K37) -> 0 | AQ37: =AVERAGE(G37,K37) -> 0 | AR37: =MEDIAN(G37,K37) -> 0
A38: 100-51-6 | B38: Benzylalkohol Halal | C38: 0.017584 | D38: 0.017884854 | E38: 0.0066947263 | G38: =+E38*$F$3 -> 0.0040168358 | H38: =+E38/D38 -> 0.37432378 | K38: =I38*$J$3 -> 0 | L38: =+I38/D38 -> 0 | O38: =+M38*$N$3 -> 0 | P38: =+M38/D38 -> 0 | S38: =+Q38*$R$3 -> 0 | T38: =+Q38/D38 -> 0 | W38: =+U38*$V$3 -> 0 | X38: =+U38/D38 -> 0 | AA38: =+Y38*$Z$3 -> 0 | AB38: =+Y38/D38 -> 0 | AE38: =+AC38*$AD$3 -> 0 | AF38: =+AC38/D38 -> 0 | AI38: =+AG38*$AH$3 -> 0 | AJ38: =+AG38/D38 -> 0 | AM38: =+AK38*$AL$3 -> 0 | AN38: =+AK38/D38 -> 0 | AP38: =SUM(G38,K38) -> 0.0040168358 | AQ38: =AVERAGE(G38,K38) -> 0.0020084179 | AR38: =MEDIAN(G38,K38) -> 0.0020084179
A39: 120-51-4 | B39: Benzylbenzoat Halal | C39: 0.013001 | D39: 0.01300534 | G39: =+E39*$F$3 -> 0 | H39: =+E39/D39 -> 0 | K39: =I39*$J$3 -> 0 | L39: =+I39/D39 -> 0 | O39: =+M39*$N$3 -> 0 | P39: =+M39/D39 -> 0 | S39: =+Q39*$R$3 -> 0 | T39: =+Q39/D39 -> 0 | W39: =+U39*$V$3 -> 0 | X39: =+U39/D39 -> 0 | AA39: =+Y39*$Z$3 -> 0 | AB39: =+Y39/D39 -> 0 | AE39: =+AC39*$AD$3 -> 0 | AF39: =+AC39/D39 -> 0 | AI39: =+AG39*$AH$3 -> 0 | AJ39: =+AG39/D39 -> 0 | AM39: =+AK39*$AL$3 -> 0 | AN39: =+AK39/D39 -> 0 | AP39: =SUM(G39,K39) -> 0 | AQ39: =AVERAGE(G39,K39) -> 0 | AR39: =MEDIAN(G39,K39) -> 0
A40: 103-37-7 | B40: Benzylbutyrat | C40: 0.005581 | D40: 0.0068829093 | G40: =+E40*$F$3 -> 0 | H40: =+E40/D40 -> 0 | K40: =I40*$J$3 -> 0 | L40: =+I40/D40 -> 0 | O40: =+M40*$N$3 -> 0 | P40: =+M40/D40 -> 0 | S40: =+Q40*$R$3 -> 0 | T40: =+Q40/D40 -> 0 | W40: =+U40*$V$3 -> 0 | X40: =+U40/D40 -> 0 | AA40: =+Y40*$Z$3 -> 0 | AB40: =+Y40/D40 -> 0 | AE40: =+AC40*$AD$3 -> 0 | AF40: =+AC40/D40 -> 0 | AI40: =+AG40*$AH$3 -> 0 | AJ40: =+AG40/D40 -> 0 | AK40: 0.0024821156 | AM40: =+AK40*$AL$3 -> 0.00099284623 | AN40: =+AK40/D40 -> 0.36062012 | AP40: =SUM(G40,K40) -> 0 | AQ40: =AVERAGE(G40,K40) -> 0 | AR40: =MEDIAN(G40,K40) -> 0
...

Sheet Rezepte_Scoring
B1: Unpleasant | C1: warm | D1: green | E1: floral | F1: citrus | G1: exotic | H1: Outlayer
A2: Rezept
A3: 188.977 | B3: =SUMPRODUCT('Übersicht Score Index'!C3:C227,Rezepte!H3:H227) -> 26.513488 | C3: =SUMPRODUCT('Übersicht Score Index'!D3:D227,Rezepte!H3:H227) -> 69.87688 | D3: =SUMPRODUCT('Übersicht Score Index'!E3:E227,Rezepte!H3:H227) -> 12.787502 | E3: =SUMPRODUCT('Übersicht Score Index'!F3:F227,Rezepte!H3:H227) -> 4.323787 | F3: =SUMPRODUCT('Übersicht Score Index'!G3:G227,Rezepte!H3:H227) -> 5.9938327 | G3: =SUMPRODUCT('Übersicht Score Index'!H3:H227,Rezepte!H3:H227) -> 8.4867592 | H3: =SUMPRODUCT('Übersicht Score Index'!I3:I227,Rezepte!H3:H227) -> 3.0581869 | I3: Warm
A4: 185.267 | B4: =SUMPRODUCT('Übersicht Score Index'!C3:C227,Rezepte!L3:L227) -> 75.684447 | C4: =SUMPRODUCT('Übersicht Score Index'!D3:D227,Rezepte!L3:L227) -> 16.019169 | D4: =SUMPRODUCT('Übersicht Score Index'!E3:E227,Rezepte!L3:L227) -> 38.283996 | E4: =SUMPRODUCT('Übersicht Score Index'!F3:F227,Rezepte!L3:L227) -> 12.276262 | F4: =SUMPRODUCT('Übersicht Score Index'!G3:G227,Rezepte!L3:L227) -> 8.2733422 | G4: =SUMPRODUCT('Übersicht Score Index'!H3:H227,Rezepte!L3:L227) -> 8.2850883 | H4: =SUMPRODUCT('Übersicht Score Index'!I3:I227,Rezepte!L3:L227) -> 0 | I4: Unpleasant
A5: 187.894 | B5: =SUMPRODUCT('Übersicht Score Index'!C3:C227,Rezepte!P3:P227) -> 18.936389 | C5: =SUMPRODUCT('Übersicht Score Index'!D3:D227,Rezepte!P3:P227) -> 29.521867 | D5: =SUMPRODUCT('Übersicht Score Index'!E3:E227,Rezepte!P3:P227) -> 48.493203 | E5: =SUMPRODUCT('Übersicht Score Index'!F3:F227,Rezepte!P3:P227) -> 245.86371 | F5: =SUMPRODUCT('Übersicht Score Index'!G3:G227,Rezepte!P3:P227) -> 4.051867 | G5: =SUMPRODUCT('Übersicht Score Index'!H3:H227,Rezepte!P3:P227) -> 5.6381342 | H5: =SUMPRODUCT('Übersicht Score Index'!I3:I227,Rezepte!P3:P227) -> 0 | I5: Walderdbeere
A6: 188.820 | B6: =SUMPRODUCT('Übersicht Score Index'!C3:C227,Rezepte!T3:T227) -> 21.942908 | C6: =SUMPRODUCT('Übersicht Score Index'!D3:D227,Rezepte!U3:U227) -> 1.2395131 | D6: =SUMPRODUCT('Übersicht Score Index'!E3:E227,Rezepte!T3:T227) -> 35.942855 | E6: =SUMPRODUCT('Übersicht Score Index'!F3:F227,Rezepte!T3:T227) -> 12.245673 | F6: =SUMPRODUCT('Übersicht Score Index'!G3:G227,Rezepte!T3:T227) -> 6.4196318 | G6: =SUMPRODUCT('Übersicht Score Index'!H3:H227,Rezepte!T3:T227) -> 7.9065777 | H6: =SUMPRODUCT('Übersicht Score Index'!I3:I227,Rezepte!T3:T227) -> 0.0015975999 | I6: Grün
A7: 188.412 | B7: =SUMPRODUCT('Übersicht Score Index'!C3:C227,Rezepte!X3:X227) -> 20.884938 | C7: =SUMPRODUCT('Übersicht Score Index'!D3:D227,Rezepte!X3:X227) -> 15.008297 | D7: =SUMPRODUCT('Übersicht Score Index'!E3:E227,Rezepte!X3:X227) -> 49.318851 | E7: =SUMPRODUCT('Übersicht Score Index'!F3:F227,Rezepte!X3:X227) -> 17.898646 | F7: =SUMPRODUCT('Übersicht Score Index'!G3:G227,Rezepte!X3:X227) -> 10.824909 | G7: =SUMPRODUCT('Übersicht Score Index'!H3:H227,Rezepte!X3:X227) -> 10.824909 | H7: =SUMPRODUCT('Übersicht Score Index'!I3:I227,Rezepte!X3:X227) -> 0 | I7: Grün
A8: 187.829 | B8: =SUMPRODUCT('Übersicht Score Index'!C3:C227,Rezepte!AB3:AB227) -> 55.021871 | C8: =SUMPRODUCT('Übersicht Score Index'!D3:D227,Rezepte!AB3:AB227) -> 54.768281 | D8: =SUMPRODUCT('Übersicht Score Index'!E3:E227,Rezepte!AB3:AB227) -> 34.261219 | E8: =SUMPRODUCT('Übersicht Score Index'!F3:F227,Rezepte!AB3:AB227) -> 1.8301772 | F8: =SUMPRODUCT('Übersicht Score Index'!G3:G227,Rezepte!AB3:AB227) -> 6.399465 | G8: =SUMPRODUCT('Übersicht Score Index'!H3:H227,Rezepte!AB3:AB227) -> 6.399465 | H8: =SUMPRODUCT('Übersicht Score Index'!I3:I227,Rezepte!AB3:AB227) -> 18.09946 | I8: Unpleasant
A9: 185.237 | B9: =SUMPRODUCT('Übersicht Score Index'!C3:C227,Rezepte!AF3:AF227) -> 31.259441 | C9: =SUMPRODUCT('Übersicht Score Index'!D3:D227,Rezepte!AF3:AF227) -> 102.21884 | D9: =SUMPRODUCT('Übersicht Score Index'!E3:E227,Rezepte!AF3:AF227) -> 27.483157 | E9: =SUMPRODUCT('Übersicht Score Index'!F3:F227,Rezepte!AF3:AF227) -> 7.4969773 | F9: =SUMPRODUCT('Übersicht Score Index'!G3:G227,Rezepte!AF3:AF227) -> 7.6484533 | G9: =SUMPRODUCT('Übersicht Score Index'!H3:H227,Rezepte!AF3:AF227) -> 7.6484533 | H9: =SUMPRODUCT('Übersicht Score Index'!I3:I227,Rezepte!AF3:AF227) -> 1.4008551 | I9: warm
A10: 185.294 | B10: =SUMPRODUCT('Übersicht Score Index'!C3:C227,Rezepte!AJ3:AJ227) -> 11.901388 | C10: =SUMPRODUCT('Übersicht Score Index'!D3:D227,Rezepte!AJ3:AJ227) -> 22.835767 | D10: =SUMPRODUCT('Übersicht Score Index'!E3:E227,Rezepte!AJ3:AJ227) -> 15.200305 | E10: =SUMPRODUCT('Übersicht Score Index'!F3:F227,Rezepte!AJ3:AJ227) -> 8.0203771 | F10: =SUMPRODUCT('Übersicht Score Index'!G3:G227,Rezepte!AJ3:AJ227) -> 4.0551335 | G10: =SUMPRODUCT('Übersicht Score Index'!H3:H227,Rezepte!AJ3:AJ227) -> 4.0551335 | H10: =SUMPRODUCT('Übersicht Score Index'!I3:I227,Rezepte!AJ3:AJ227) -> 1.4936247 | I10: dairy
A11: 187.776 | B11: =SUMPRODUCT('Übersicht Score Index'!C3:C227,Rezepte!AN3:AN227) -> 4.8964045 | C11: =SUMPRODUCT('Übersicht Score Index'!D3:D227,Rezepte!AN3:AN227) -> 56.175626 | D11: =SUMPRODUCT('Übersicht Score Index'!E3:E227,Rezepte!AN3:AN227) -> 16.324223 | E11: =SUMPRODUCT('Übersicht Score Index'!F3:F227,Rezepte!AN3:AN227) -> 75.005359 | F11: =SUMPRODUCT('Übersicht Score Index'!G3:G227,Rezepte!AN3:AN227) -> 4.8778818 | G11: =SUMPRODUCT('Übersicht Score Index'!H3:H227,Rezepte!AN3:AN227) -> 4.8778818 | H11: =SUMPRODUCT('Übersicht Score Index'!I3:I227,Rezepte!AN3:AN227) -> 0.0020580743 | I11: floral
B27: Unpleasant | C27: warm | D27: green | E27: floral | F27: citrus | G27: exotic | H27: Outlayer
A28: Rezept
A29: 188.977 | C29: 0.94100141 | D29: 0.43996577 | E29: 0.38168323 | F29: 0.25946663 | G29: 0.25946663 | H29: 0.043954662 | I29: Warm
A30: 185.267 | B30: 0.83270455 | C30: 0.45710227 | D30: 0.01825 | E30: 0.47754545 | F30: 0.26486364 | G30: 0.12302273 | H30: 0 | I30: Unpleasant
A31: 187.894 | B31: 0.058151885 | C31: 0.1217314 | D31: 0.14439724 | E31: 0.039298671 | F31: 0.052512543 | G31: 0.038724763 | H31: 0.04458282 | I31: Walderdbeere

Sheet Rohstoffe_im_Cluster_Scoring
A1: CAS Nr. | B1: Rohstoff | C1: Unpleasant Score | F1: warm | I1: green | L1: floral | O1: citrus | R1: exotic | U1: Outlayer
C2: Summe | D2: Mittelwert | E2: Median | F2: Summe | G2: Mittelwert | H2: Median | I2: Summe | J2: Mittelwert | K2: Median | L2: Summe | M2: Mittelwert | N2: Median | O2: Summe | P2: Mittelwert | Q2: Median | R2: Summe | S2: Mittelwert | T2: Median | U2: Summe | V2: Mittelwert | W2: Median
A3: 14667-55-1 | B3: 2,3,5-Trimethylpyrazin, natürlich Halal | C3: ='Übersicht Score Index'!C3*Rezepte!AP3 -> 0.005239351 | D3: ='Übersicht Score Index'!C3*Rezepte!AQ3 -> 0.0015718053 | E3: ='Übersicht Score Index'!C3*Rezepte!AR3 -> 0.0015718053 | F3: ='Übersicht Score Index'!D3*Rezepte!AP3 -> 0.005239351 | G3: ='Übersicht Score Index'!D3*Rezepte!AQ3 -> 0.0015718053 | H3: ='Übersicht Score Index'!D3*Rezepte!AR3 -> 0.0015718053 | I3: ='Übersicht Score Index'!E3*Rezepte!AP3 -> 0 | J3: ='Übersicht Score Index'!E3*Rezepte!AQ3 -> 0 | K3: ='Übersicht Score Index'!E3*Rezepte!AR3 -> 0 | L3: ='Übersicht Score Index'!F3*Rezepte!AP3 -> 0 | M3: ='Übersicht Score Index'!F3*Rezepte!AQ3 -> 0 | N3: ='Übersicht Score Index'!F3*Rezepte!AR3 -> 0 | O3: ='Übersicht Score Index'!G3*Rezepte!AP3 -> 0 | P3: ='Übersicht Score Index'!G3*Rezepte!AQ3 -> 0 | Q3: ='Übersicht Score Index'!G3*Rezepte!AR3 -> 0 | R3: ='Übersicht Score Index'!H3*Rezepte!AP3 -> 0 | S3: ='Übersicht Score Index'!H3*Rezepte!AQ3 -> 0 | T3: ='Übersicht Score Index'!H3*Rezepte!AR3 -> 0 | U3: ='Übersicht Score Index'!I3*Rezepte!AP3 -> 0.005239351 | V3: ='Übersicht Score Index'!I3*Rezepte!AQ3 -> 0.0015718053 | W3: ='Übersicht Score Index'!I3*Rezepte!AR3 -> 0.0015718053
A4: 1192-62-7 | B4: 2-Acetylfuran, natürlich | C4: ='Übersicht Score Index'!C4*Rezepte!AP4 -> 0 | D4: ='Übersicht Score Index'!C4*Rezepte!AQ4 -> 0 | E4: ='Übersicht Score Index'!C4*Rezepte!AR4 -> 0 | F4: ='Übersicht Score Index'!D4*Rezepte!AP4 -> 0 | G4: ='Übersicht Score Index'!D4*Rezepte!AQ4 -> 0 | H4: ='Übersicht Score Index'!D4*Rezepte!AR4 -> 0 | I4: ='Übersicht Score Index'!E4*Rezepte!AP4 -> 0 | J4: ='Übersicht Score Index'!E4*Rezepte!AQ4 -> 0 | K4: ='Übersicht Score Index'!E4*Rezepte!AR4 -> 0 | L4: ='Übersicht Score Index'!F4*Rezepte!AP4 -> 0 | M4: ='Übersicht Score Index'!F4*Rezepte!AQ4 -> 0 | N4: ='Übersicht Score Index'!F4*Rezepte!AR4 -> 0 | O4: ='Übersicht Score Index'!G4*Rezepte!AP4 -> 0 | P4: ='Übersicht Score Index'!G4*Rezepte!AQ4 -> 0 | Q4: ='Übersicht Score Index'!G4*Rezepte!AR4 -> 0 | R4: ='Übersicht Score Index'!H4*Rezepte!AP4 -> 0 | S4: ='Übersicht Score Index'!H4*Rezepte!AQ4 -> 0 | T4: ='Übersicht Score Index'!H4*Rezepte!AR4 -> 0 | U4: ='Übersicht Score Index'!I4*Rezepte!AP4 -> 0 | V4: ='Übersicht Score Index'!I4*Rezepte!AQ4 -> 0 | W4: ='Übersicht Score Index'!I4*Rezepte!AR4 -> 0
A5: 15679-12-6 | B5: 2-Ethyl-4-methylthiazol, natürlich | C5: ='Übersicht Score Index'!C5*Rezepte!AP5 -> 0 | D5: ='Übersicht Score Index'!C5*Rezepte!AQ5 -> 0 | E5: ='Übersicht Score Index'!C5*Rezepte!AR5 -> 0 | F5: ='Übersicht Score Index'!D5*Rezepte!AP5 -> 0 | G5: ='Übersicht Score Index'!D5*Rezepte!AQ5 -> 0 | H5: ='Übersicht Score Index'!D5*Rezepte!AR5 -> 0 | I5: ='Übersicht Score Index'!E5*Rezepte!AP5 -> 0 | J5: ='Übersicht Score Index'!E5*Rezepte!AQ5 -> 0 | K5: ='Übersicht Score Index'!E5*Rezepte!AR5 -> 0 | L5: ='Übersicht Score Index'!F5*Rezepte!AP5 -> 0 | M5: ='Übersicht Score Index'!F5*Rezepte!AQ5 -> 0 | N5: ='Übersicht Score Index'!F5*Rezepte!AR5 -> 0 | O5: ='Übersicht Score Index'!G5*Rezepte!AP5 -> 0 | P5: ='Übersicht Score Index'!G5*Rezepte!AQ5 -> 0 | Q5: ='Übersicht Score Index'!G5*Rezepte!AR5 -> 0 | R5: ='Übersicht Score Index'!H5*Rezepte!AP5 -> 0 | S5: ='Übersicht Score Index'!H5*Rezepte!AQ5 -> 0 | T5: ='Übersicht Score Index'!H5*Rezepte!AR5 -> 0 | U5: ='Übersicht Score Index'!I5*Rezepte!AP5 -> 0 | V5: ='Übersicht Score Index'!I5*Rezepte!AQ5 -> 0 | W5: ='Übersicht Score Index'!I5*Rezepte!AR5 -> 0
A6: 110-43-0 | B6: 2-Heptanon Halal | C6: ='Übersicht Score Index'!C6*Rezepte!AP6 -> 0 | D6: ='Übersicht Score Index'!C6*Rezepte!AQ6 -> 0 | E6: ='Übersicht Score Index'!C6*Rezepte!AR6 -> 0 | F6: ='Übersicht Score Index'!D6*Rezepte!AP6 -> 0 | G6: ='Übersicht Score Index'!D6*Rezepte!AQ6 -> 0 | H6: ='Übersicht Score Index'!D6*Rezepte!AR6 -> 0 | I6: ='Übersicht Score Index'!E6*Rezepte!AP6 -> 0 | J6: ='Übersicht Score Index'!E6*Rezepte!AQ6 -> 0 | K6: ='Übersicht Score Index'!E6*Rezepte!AR6 -> 0 | L6: ='Übersicht Score Index'!F6*Rezepte!AP6 -> 0 | M6: ='Übersicht Score Index'!F6*Rezepte!AQ6 -> 0 | N6: ='Übersicht Score Index'!F6*Rezepte!AR6 -> 0 | O6: ='Übersicht Score Index'!G6*Rezepte!AP6 -> 0 | P6: ='Übersicht Score Index'!G6*Rezepte!AQ6 -> 0 | Q6: ='Übersicht Score Index'!G6*Rezepte!AR6 -> 0 | R6: ='Übersicht Score Index'!H6*Rezepte!AP6 -> 0 | S6: ='Übersicht Score Index'!H6*Rezepte!AQ6 -> 0 | T6: ='Übersicht Score Index'!H6*Rezepte!AR6 -> 0 | U6: ='Übersicht Score Index'!I6*Rezepte!AP6 -> 0 | V6: ='Übersicht Score Index'!I6*Rezepte!AQ6 -> 0 | W6: ='Übersicht Score Index'!I6*Rezepte!AR6 -> 0
A7: 137-32-6 | B7: 2-Methyl-1-butanol, natürlich Kosher Halal | C7: ='Übersicht Score Index'!C7*Rezepte!AP7 -> 0 | D7: ='Übersicht Score Index'!C7*Rezepte!AQ7 -> 0 | E7: ='Übersicht Score Index'!C7*Rezepte!AR7 -> 0 | F7: ='Übersicht Score Index'!D7*Rezepte!AP7 -> 0 | G7: ='Übersicht Score Index'!D7*Rezepte!AQ7 -> 0 | H7: ='Übersicht Score Index'!D7*Rezepte!AR7 -> 0 | I7: ='Übersicht Score Index'!E7*Rezepte!AP7 -> 0 | J7: ='Übersicht Score Index'!E7*Rezepte!AQ7 -> 0 | K7: ='Übersicht Score Index'!E7*Rezepte!AR7 -> 0 | L7: ='Übersicht Score Index'!F7*Rezepte!AP7 -> 0 | M7: ='Übersicht Score Index'!F7*Rezepte!AQ7 -> 0 | N7: ='Übersicht Score Index'!F7*Rezepte!AR7 -> 0 | O7: ='Übersicht Score Index'!G7*Rezepte!AP7 -> 0 | P7: ='Übersicht Score Index'!G7*Rezepte!AQ7 -> 0 | Q7: ='Übersicht Score Index'!G7*Rezepte!AR7 -> 0 | R7: ='Übersicht Score Index'!H7*Rezepte!AP7 -> 0 | S7: ='Übersicht Score Index'!H7*Rezepte!AQ7 -> 0 | T7: ='Übersicht Score Index'!H7*Rezepte!AR7 -> 0 | U7: ='Übersicht Score Index'!I7*Rezepte!AP7 -> 0 | V7: ='Übersicht Score Index'!I7*Rezepte!AQ7 -> 0 | W7: ='Übersicht Score Index'!I7*Rezepte!AR7 -> 0
A8: 3142-72-1 | B8: 2-Methyl-2-pentensäure | C8: ='Übersicht Score Index'!C8*Rezepte!AP8 -> 0 | D8: ='Übersicht Score Index'!C8*Rezepte!AQ8 -> 0 | E8: ='Übersicht Score Index'!C8*Rezepte!AR8 -> 0 | F8: ='Übersicht Score Index'!D8*Rezepte!AP8 -> 0 | G8: ='Übersicht Score Index'!D8*Rezepte!AQ8 -> 0 | H8: ='Übersicht Score Index'!D8*Rezepte!AR8 -> 0 | I8: ='Übersicht Score Index'!E8*Rezepte!AP8 -> 0 | J8: ='Übersicht Score Index'!E8*Rezepte!AQ8 -> 0 | K8: ='Übersicht Score Index'!E8*Rezepte!AR8 -> 0 | L8: ='Übersicht Score Index'!F8*Rezepte!AP8 -> 0 | M8: ='Übersicht Score Index'!F8*Rezepte!AQ8 -> 0 | N8: ='Übersicht Score Index'!F8*Rezepte!AR8 -> 0 | O8: ='Übersicht Score Index'!G8*Rezepte!AP8 -> 0 | P8: ='Übersicht Score Index'!G8*Rezepte!AQ8 -> 0 | Q8: ='Übersicht Score Index'!G8*Rezepte!AR8 -> 0 | R8: ='Übersicht Score Index'!H8*Rezepte!AP8 -> 0 | S8: ='Übersicht Score Index'!H8*Rezepte!AQ8 -> 0 | T8: ='Übersicht Score Index'!H8*Rezepte!AR8 -> 0 | U8: ='Übersicht Score Index'!I8*Rezepte!AP8 -> 0 | V8: ='Übersicht Score Index'!I8*Rezepte!AQ8 -> 0 | W8: ='Übersicht Score Index'!I8*Rezepte!AR8 -> 0
A9: 116-53-0 | B9: 2-Methylbuttersäure Halal Kosher | C9: ='Übersicht Score Index'!C9*Rezepte!AP9 -> 0.36250576 | D9: ='Übersicht Score Index'!C9*Rezepte!AQ9 -> 0.18125288 | E9: ='Übersicht Score Index'!C9*Rezepte!AR9 -> 0.18125288 | F9: ='Übersicht Score Index'!D9*Rezepte!AP9 -> 0.36250576 | G9: ='Übersicht Score Index'!D9*Rezepte!AQ9 -> 0.18125288 | H9: ='Übersicht Score Index'!D9*Rezepte!AR9 -> 0.18125288 | I9: ='Übersicht Score Index'!E9*Rezepte!AP9 -> 0 | J9: ='Übersicht Score Index'!E9*Rezepte!AQ9 -> 0 | K9: ='Übersicht Score Index'!E9*Rezepte!AR9 -> 0 | L9: ='Übersicht Score Index'!F9*Rezepte!AP9 -> 0 | M9: ='Übersicht Score Index'!F9*Rezepte!AQ9 -> 0 | N9: ='Übersicht Score Index'!F9*Rezepte!AR9 -> 0 | O9: ='Übersicht Score Index'!G9*Rezepte!AP9 -> 0.36250576 | P9: ='Übersicht Score Index'!G9*Rezepte!AQ9 -> 0.18125288 | Q9: ='Übersicht Score Index'!G9*Rezepte!AR9 -> 0.18125288 | R9: ='Übersicht Score Index'!H9*Rezepte!AP9 -> 0.36250576 | S9: ='Übersicht Score Index'!H9*Rezepte!AQ9 -> 0.18125288 | T9: ='Übersicht Score Index'!H9*Rezepte!AR9 -> 0.18125288 | U9: ='Übersicht Score Index'!I9*Rezepte!AP9 -> 0 | V9: ='Übersicht Score Index'!I9*Rezepte!AQ9 -> 0 | W9: ='Übersicht Score Index'!I9*Rezepte!AR9 -> 0
A10: 2445-78-5 | B10: 2-Methylbutyl-2-methylbutyrat | C10: ='Übersicht Score Index'!C10*Rezepte!AP10 -> 0 | D10: ='Übersicht Score Index'!C10*Rezepte!AQ10 -> 0 | E10: ='Übersicht Score Index'!C10*Rezepte!AR10 -> 0 | F10: ='Übersicht Score Index'!D10*Rezepte!AP10 -> 0 | G10: ='Übersicht Score Index'!D10*Rezepte!AQ10 -> 0 | H10: ='Übersicht Score Index'!D10*Rezepte!AR10 -> 0 | I10: ='Übersicht Score Index'!E10*Rezepte!AP10 -> 0 | J10: ='Übersicht Score Index'!E10*Rezepte!AQ10 -> 0 | K10: ='Übersicht Score Index'!E10*Rezepte!AR10 -> 0 | L10: ='Übersicht Score Index'!F10*Rezepte!AP10 -> 0 | M10: ='Übersicht Score Index'!F10*Rezepte!AQ10 -> 0 | N10: ='Übersicht Score Index'!F10*Rezepte!AR10 -> 0 | O10: ='Übersicht Score Index'!G10*Rezepte!AP10 -> 0 | P10: ='Übersicht Score Index'!G10*Rezepte!AQ10 -> 0 | Q10: ='Übersicht Score Index'!G10*Rezepte!AR10 -> 0 | R10: ='Übersicht Score Index'!H10*Rezepte!AP10 -> 0 | S10: ='Übersicht Score Index'!H10*Rezepte!AQ10 -> 0 | T10: ='Übersicht Score Index'!H10*Rezepte!AR10 -> 0 | U10: ='Übersicht Score Index'!I10*Rezepte!AP10 -> 0 | V10: ='Übersicht Score Index'!I10*Rezepte!AQ10 -> 0 | W10: ='Übersicht Score Index'!I10*Rezepte!AR10 -> 0
A11: 624-41-9 | B11: 2-Methylbutylacetat Kosher Halal | C11: ='Übersicht Score Index'!C11*Rezepte!AP11 -> 0 | D11: ='Übersicht Score Index'!C11*Rezepte!AQ11 -> 0 | E11: ='Übersicht Score Index'!C11*Rezepte!AR11 -> 0 | F11: ='Übersicht Score Index'!D11*Rezepte!AP11 -> 0 | G11: ='Übersicht Score Index'!D11*Rezepte!AQ11 -> 0 | H11: ='Übersicht Score Index'!D11*Rezepte!AR11 -> 0 | I11: ='Übersicht Score Index'!E11*Rezepte!AP11 -> 0 | J11: ='Übersicht Score Index'!E11*Rezepte!AQ11 -> 0 | K11: ='Übersicht Score Index'!E11*Rezepte!AR11 -> 0 | L11: ='Übersicht Score Index'!F11*Rezepte!AP11 -> 0 | M11: ='Übersicht Score Index'!F11*Rezepte!AQ11 -> 0 | N11: ='Übersicht Score Index'!F11*Rezepte!AR11 -> 0 | O11: ='Übersicht Score Index'!G11*Rezepte!AP11 -> 0 | P11: ='Übersicht Score Index'!G11*Rezepte!AQ11 -> 0 | Q11: ='Übersicht Score Index'!G11*Rezepte!AR11 -> 0 | R11: ='Übersicht Score Index'!H11*Rezepte!AP11 -> 0 | S11: ='Übersicht Score Index'!H11*Rezepte!AQ11 -> 0 | T11: ='Übersicht Score Index'!H11*Rezepte!AR11 -> 0 | U11: ='Übersicht Score Index'!I11*Rezepte!AP11 -> 0 | V11: ='Übersicht Score Index'!I11*Rezepte!AQ11 -> 0 | W11: ='Übersicht Score Index'!I11*Rezepte!AR11 -> 0
A12: 51115-64-1 | B12: 2-Methylbutylbutyrat | C12: ='Übersicht Score Index'!C12*Rezepte!AP12 -> 0 | D12: ='Übersicht Score Index'!C12*Rezepte!AQ12 -> 0 | E12: ='Übersicht Score Index'!C12*Rezepte!AR12 -> 0 | F12: ='Übersicht Score Index'!D12*Rezepte!AP12 -> 0 | G12: ='Übersicht Score Index'!D12*Rezepte!AQ12 -> 0 | H12: ='Übersicht Score Index'!D12*Rezepte!AR12 -> 0 | I12: ='Übersicht Score Index'!E12*Rezepte!AP12 -> 0 | J12: ='Übersicht Score Index'!E12*Rezepte!AQ12 -> 0 | K12: ='Übersicht Score Index'!E12*Rezepte!AR12 -> 0 | L12: ='Übersicht Score Index'!F12*Rezepte!AP12 -> 0 | M12: ='Übersicht Score Index'!F12*Rezepte!AQ12 -> 0 | N12: ='Übersicht Score Index'!F12*Rezepte!AR12 -> 0 | O12: ='Übersicht Score Index'!G12*Rezepte!AP12 -> 0 | P12: ='Übersicht Score Index'!G12*Rezepte!AQ12 -> 0 | Q12: ='Übersicht Score Index'!G12*Rezepte!AR12 -> 0 | R12: ='Übersicht Score Index'!H12*Rezepte!AP12 -> 0 | S12: ='Übersicht Score Index'!H12*Rezepte!AQ12 -> 0 | T12: ='Übersicht Score Index'!H12*Rezepte!AR12 -> 0 | U12: ='Übersicht Score Index'!I12*Rezepte!AP12 -> 0 | V12: ='Übersicht Score Index'!I12*Rezepte!AQ12 -> 0 | W12: ='Übersicht Score Index'!I12*Rezepte!AR12 -> 0
A13: 2445-77-4 | B13: 2-Methylbutylisovalerat | C13: ='Übersicht Score Index'!C13*Rezepte!AP13 -> 0 | D13: ='Übersicht Score Index'!C13*Rezepte!AQ13 -> 0 | E13: ='Übersicht Score Index'!C13*Rezepte!AR13 -> 0 | F13: ='Übersicht Score Index'!D13*Rezepte!AP13 -> 0 | G13: ='Übersicht Score Index'!D13*Rezepte!AQ13 -> 0 | H13: ='Übersicht Score Index'!D13*Rezepte!AR13 -> 0 | I13: ='Übersicht Score Index'!E13*Rezepte!AP13 -> 0 | J13: ='Übersicht Score Index'!E13*Rezepte!AQ13 -> 0 | K13: ='Übersicht Score Index'!E13*Rezepte!AR13 -> 0 | L13: ='Übersicht Score Index'!F13*Rezepte!AP13 -> 0 | M13: ='Übersicht Score Index'!F13*Rezepte!AQ13 -> 0 | N13: ='Übersicht Score Index'!F13*Rezepte!AR13 -> 0 | O13: ='Übersicht Score Index'!G13*Rezepte!AP13 -> 0 | P13: ='Übersicht Score Index'!G13*Rezepte!AQ13 -> 0 | Q13: ='Übersicht Score Index'!G13*Rezepte!AR13 -> 0 | R13: ='Übersicht Score Index'!H13*Rezepte!AP13 -> 0 | S13: ='Übersicht Score Index'!H13*Rezepte!AQ13 -> 0 | T13: ='Übersicht Score Index'!H13*Rezepte!AR13 -> 0 | U13: ='Übersicht Score Index'!I13*Rezepte!AP13 -> 0 | V13: ='Übersicht Score Index'!I13*Rezepte!AQ13 -> 0 | W13: ='Übersicht Score Index'!I13*Rezepte!AR13 -> 0
A14: 821-55-6 | B14: 2-Nonanon, natürlich Halal | C14: ='Übersicht Score Index'!C14*Rezepte!AP14 -> 0 | D14: ='Übersicht Score Index'!C14*Rezepte!AQ14 -> 0 | E14: ='Übersicht Score Index'!C14*Rezepte!AR14 -> 0 | F14: ='Übersicht Score Index'!D14*Rezepte!AP14 -> 0 | G14: ='Übersicht Score Index'!D14*Rezepte!AQ14 -> 0 | H14: ='Übersicht Score Index'!D14*Rezepte!AR14 -> 0 | I14: ='Übersicht Score Index'!E14*Rezepte!AP14 -> 0 | J14: ='Übersicht Score Index'!E14*Rezepte!AQ14 -> 0 | K14: ='Übersicht Score Index'!E14*Rezepte!AR14 -> 0 | L14: ='Übersicht Score Index'!F14*Rezepte!AP14 -> 0 | M14: ='Übersicht Score Index'!F14*Rezepte!AQ14 -> 0 | N14: ='Übersicht Score Index'!F14*Rezepte!AR14 -> 0 | O14: ='Übersicht Score Index'!G14*Rezepte!AP14 -> 0 | P14: ='Übersicht Score Index'!G14*Rezepte!AQ14 -> 0 | Q14: ='Übersicht Score Index'!G14*Rezepte!AR14 -> 0 | R14: ='Übersicht Score Index'!H14*Rezepte!AP14 -> 0 | S14: ='Übersicht Score Index'!H14*Rezepte!AQ14 -> 0 | T14: ='Übersicht Score Index'!H14*Rezepte!AR14 -> 0 | U14: ='Übersicht Score Index'!I14*Rezepte!AP14 -> 0 | V14: ='Übersicht Score Index'!I14*Rezepte!AQ14 -> 0 | W14: ='Übersicht Score Index'!I14*Rezepte!AR14 -> 0
... A22: 3390-12-3 | B22: Acetaldehyd PG acetal | C22: ='Übersicht Score Index'!C22*Rezepte!AP22 -> 0 | D22: ='Übersicht Score Index'!C22*Rezepte!AQ22 -> 0 | E22: ='Übersicht Score Index'!C22*Rezepte!AR22 -> 0 | F22: ='Übersicht Score Index'!D22*Rezepte!AP22 -> 0 | G22: ='Übersicht Score Index'!D22*Rezepte!AQ22 -> 0 | H22: ='Übersicht Score Index'!D22*Rezepte!AR22 -> 0 | I22: ='Übersicht Score Index'!E22*Rezepte!AP22 -> 0 | J22: ='Übersicht Score Index'!E22*Rezepte!AQ22 -> 0 | K22: ='Übersicht Score Index'!E22*Rezepte!AR22 -> 0 | L22: ='Übersicht Score Index'!F22*Rezepte!AP22 -> 0 | M22: ='Übersicht Score Index'!F22*Rezepte!AQ22 -> 0 | N22: ='Übersicht Score Index'!F22*Rezepte!AR22 -> 0 | O22: ='Übersicht Score Index'!G22*Rezepte!AP22 -> 0 | P22: ='Übersicht Score Index'!G22*Rezepte!AQ22 -> 0 | Q22: ='Übersicht Score Index'!G22*Rezepte!AR22 -> 0 | R22: ='Übersicht Score Index'!H22*Rezepte!AP22 -> 0 | S22: ='Übersicht Score Index'!H22*Rezepte!AQ22 -> 0 | T22: ='Übersicht Score Index'!H22*Rezepte!AR22 -> 0 | U22: ='Übersicht Score Index'!I22*Rezepte!AP22 -> 0 | V22: ='Übersicht Score Index'!I22*Rezepte!AQ22 -> 0 | W22: ='Übersicht Score Index'!I22*Rezepte!AR22 -> 0
A23: 513-86-0 | B23: Acetoin 50% in PG Kosher Halal | C23: ='Übersicht Score Index'!C23*Rezepte!#REF! -> #REF! | D23: ='Übersicht Score Index'!C23*Rezepte!#REF! -> #REF! | E23: ='Übersicht Score Index'!C23*Rezepte!#REF! -> #REF! | F23: ='Übersicht Score Index'!D23*Rezepte!#REF! -> #REF! | G23: ='Übersicht Score Index'!D23*Rezepte!#REF! -> #REF! | H23: ='Übersicht Score Index'!D23*Rezepte!#REF! -> #REF! | I23: ='Übersicht Score Index'!E23*Rezepte!#REF! -> #REF! | J23: ='Übersicht Score Index'!E23*Rezepte!#REF! -> #REF! | K23: ='Übersicht Score Index'!E23*Rezepte!#REF! -> #REF! | L23: ='Übersicht Score Index'!F23*Rezepte!#REF! -> #REF! | M23: ='Übersicht Score Index'!F23*Rezepte!#REF! -> #REF! | N23: ='Übersicht Score Index'!F23*Rezepte!#REF! -> #REF! | O23: ='Übersicht Score Index'!G23*Rezepte!#REF! -> #REF! | P23: ='Übersicht Score Index'!G23*Rezepte!#REF! -> #REF! | Q23: ='Übersicht Score Index'!G23*Rezepte!#REF! -> #REF! | R23: ='Übersicht Score Index'!H23*Rezepte!#REF! -> #REF! | S23: ='Übersicht Score Index'!H23*Rezepte!#REF! -> #REF! | T23: ='Übersicht Score Index'!H23*Rezepte!#REF! -> #REF! | U23: ='Übersicht Score Index'!I23*Rezepte!#REF! -> #REF! | V23: ='Übersicht Score Index'!I23*Rezepte!#REF! -> #REF! | W23: ='Übersicht Score Index'!I23*Rezepte!#REF! -> #REF!
A24: 67-64-1 | B24: Aceton | C24: ='Übersicht Score Index'!C24*Rezepte!AP24 -> 0 | D24: ='Übersicht Score Index'!C24*Rezepte!AQ24 -> 0 | E24: ='Übersicht Score Index'!C24*Rezepte!AR24 -> 0 | F24: ='Übersicht Score Index'!D24*Rezepte!AP24 -> 0 | G24: ='Übersicht Score Index'!D24*Rezepte!AQ24 -> 0 | H24: ='Übersicht Score Index'!D24*Rezepte!AR24 -> 0 | I24: ='Übersicht Score Index'!E24*Rezepte!AP24 -> 0 | J24: ='Übersicht Score Index'!E24*Rezepte!AQ24 -> 0 | K24: ='Übersicht Score Index'!E24*Rezepte!AR24 -> 0 | L24: ='Übersicht Score Index'!F24*Rezepte!AP24 -> 0 | M24: ='Übersicht Score Index'!F24*Rezepte!AQ24 -> 0 | N24: ='Übersicht Score Index'!F24*Rezepte!AR24 -> 0 | O24: ='Übersicht Score Index'!G24*Rezepte!AP24 -> 0 | P24: ='Übersicht Score Index'!G24*Rezepte!AQ24 -> 0 | Q24: ='Übersicht Score Index'!G24*Rezepte!AR24 -> 0 | R24: ='Übersicht Score Index'!H24*Rezepte!AP24 -> 0 | S24: ='Übersicht Score Index'!H24*Rezepte!AQ24 -> 0 | T24: ='Übersicht Score Index'!H24*Rezepte!AR24 -> 0 | U24: ='Übersicht Score Index'!I24*Rezepte!AP24 -> 0 | V24: ='Übersicht Score Index'!I24*Rezepte!AQ24 -> 0 | W24: ='Übersicht Score Index'!I24*Rezepte!AR24 -> 0
A25: 98-86-2 | B25: Acetophenon, natürlich Halal | C25: ='Übersicht Score Index'!C25*Rezepte!AP25 -> 0 | D25: ='Übersicht Score Index'!C25*Rezepte!AQ25 -> 0 | E25: ='Übersicht Score Index'!C25*Rezepte!AR25 -> 0 | F25: ='Übersicht Score Index'!D25*Rezepte!AP25 -> 0 | G25: ='Übersicht Score Index'!D25*Rezepte!AQ25 -> 0 | H25: ='Übersicht Score Index'!D25*Rezepte!AR25 -> 0 | I25: ='Übersicht Score Index'!E25*Rezepte!AP25 -> 0 | J25: ='Übersicht Score Index'!E25*Rezepte!AQ25 -> 0 | K25: ='Übersicht Score Index'!E25*Rezepte!AR25 -> 0 | L25: ='Übersicht Score Index'!F25*Rezepte!AP25 -> 0 | M25: ='Übersicht Score Index'!F25*Rezepte!AQ25 -> 0 | N25: ='Übersicht Score Index'!F25*Rezepte!AR25 -> 0 | O25: ='Übersicht Score Index'!G25*Rezepte!AP25 -> 0 | P25: ='Übersicht Score Index'!G25*Rezepte!AQ25 -> 0 | Q25: ='Übersicht Score Index'!G25*Rezepte!AR25 -> 0 | R25: ='Übersicht Score Index'!H25*Rezepte!AP25 -> 0 | S25: ='Übersicht Score Index'!H25*Rezepte!AQ25 -> 0 | T25: ='Übersicht Score Index'!H25*Rezepte!AR25 -> 0 | U25: ='Übersicht Score Index'!I25*Rezepte!AP25 -> 0 | V25: ='Übersicht Score Index'!I25*Rezepte!AQ25 -> 0 | W25: ='Übersicht Score Index'!I25*Rezepte!AR25 -> 0
A26: 2719-08-6 | B26: Acetyl N-methylanthranilat | C26: ='Übersicht Score Index'!C26*Rezepte!AP26 -> 0 | D26: ='Übersicht Score Index'!C26*Rezepte!AQ26 -> 0 | E26: ='Übersicht Score Index'!C26*Rezepte!AR26 -> 0 | F26: ='Übersicht Score Index'!D26*Rezepte!AP26 -> 0 | G26: ='Übersicht Score Index'!D26*Rezepte!AQ26 -> 0 | H26: ='Übersicht Score Index'!D26*Rezepte!AR26 -> 0 | I26: ='Übersicht Score Index'!E26*Rezepte!AP26 -> 0 | J26: ='Übersicht Score Index'!E26*Rezepte!AQ26 -> 0 | K26: ='Übersicht Score Index'!E26*Rezepte!AR26 -> 0 | L26: ='Übersicht Score Index'!F26*Rezepte!AP26 -> 0 | M26: ='Übersicht Score Index'!F26*Rezepte!AQ26 -> 0 | N26: ='Übersicht Score Index'!F26*Rezepte!AR26 -> 0 | O26: ='Übersicht Score Index'!G26*Rezepte!AP26 -> 0 | P26: ='Übersicht Score Index'!G26*Rezepte!AQ26 -> 0 | Q26: ='Übersicht Score Index'!G26*Rezepte!AR26 -> 0 | R26: ='Übersicht Score Index'!H26*Rezepte!AP26 -> 0 | S26: ='Übersicht Score Index'!H26*Rezepte!AQ26 -> 0 | T26: ='Übersicht Score Index'!H26*Rezepte!AR26 -> 0 | U26: ='Übersicht Score Index'!I26*Rezepte!AP26 -> 0 | V26: ='Übersicht Score Index'!I26*Rezepte!AQ26 -> 0 | W26: ='Übersicht Score Index'!I26*Rezepte!AR26 -> 0
A27: 600-14-6 | B27: Acetylpropionyl Halal | C27: ='Übersicht Score Index'!C27*Rezepte!AP27 -> 0 | D27: ='Übersicht Score Index'!C27*Rezepte!AQ27 -> 0 | E27: ='Übersicht Score Index'!C27*Rezepte!AR27 -> 0 | F27: ='Übersicht Score Index'!D27*Rezepte!AP27 -> 0 | G27: ='Übersicht Score Index'!D27*Rezepte!AQ27 -> 0 | H27: ='Übersicht Score Index'!D27*Rezepte!AR27 -> 0 | I27: ='Übersicht Score Index'!E27*Rezepte!AP27 -> 0 | J27: ='Übersicht Score Index'!E27*Rezepte!AQ27 -> 0 | K27: ='Übersicht Score Index'!E27*Rezepte!AR27 -> 0 | L27: ='Übersicht Score Index'!F27*Rezepte!AP27 -> 0 | M27: ='Übersicht Score Index'!F27*Rezepte!AQ27 -> 0 | N27: ='Übersicht Score Index'!F27*Rezepte!AR27 -> 0 | O27: ='Übersicht Score Index'!G27*Rezepte!AP27 -> 0 | P27: ='Übersicht Score Index'!G27*Rezepte!AQ27 -> 0 | Q27: ='Übersicht Score Index'!G27*Rezepte!AR27 -> 0 | R27: ='Übersicht Score Index'!H27*Rezepte!AP27 -> 0 | S27: ='Übersicht Score Index'!H27*Rezepte!AQ27 -> 0 | T27: ='Übersicht Score Index'!H27*Rezepte!AR27 -> 0 | U27: ='Übersicht Score Index'!I27*Rezepte!AP27 -> 0 | V27: ='Übersicht Score Index'!I27*Rezepte!AQ27 -> 0 | W27: ='Übersicht Score Index'!I27*Rezepte!AR27 -> 0
A28: 123-68-2 | B28: Allylhexanoat, natürlich Halal | C28: ='Übersicht Score Index'!C28*Rezepte!AP28 -> 0 | D28: ='Übersicht Score Index'!C28*Rezepte!AQ28 -> 0 | E28: ='Übersicht Score Index'!C28*Rezepte!AR28 -> 0 | F28: ='Übersicht Score Index'!D28*Rezepte!AP28 -> 0 | G28: ='Übersicht Score Index'!D28*Rezepte!AQ28 -> 0 | H28: ='Übersicht Score Index'!D28*Rezepte!AR28 -> 0 | I28: ='Übersicht Score Index'!E28*Rezepte!AP28 -> 0 | J28: ='Übersicht Score Index'!E28*Rezepte!AQ28 -> 0 | K28: ='Übersicht Score Index'!E28*Rezepte!AR28 -> 0 | L28: ='Übersicht Score Index'!F28*Rezepte!AP28 -> 0 | M28: ='Übersicht Score Index'!F28*Rezepte!AQ28 -> 0 | N28: ='Übersicht Score Index'!F28*Rezepte!AR28 -> 0 | O28: ='Übersicht Score Index'!G28*Rezepte!AP28 -> 0 | P28: ='Übersicht Score Index'!G28*Rezepte!AQ28 -> 0 | Q28: ='Übersicht Score Index'!G28*Rezepte!AR28 -> 0 | R28: ='Übersicht Score Index'!H28*Rezepte!AP28 -> 0 | S28: ='Übersicht Score Index'!H28*Rezepte!AQ28 -> 0 | T28: ='Übersicht Score Index'!H28*Rezepte!AR28 -> 0 | U28: ='Übersicht Score Index'!I28*Rezepte!AP28 -> 0 | V28: ='Übersicht Score Index'!I28*Rezepte!AQ28 -> 0 | W28: ='Übersicht Score Index'!I28*Rezepte!AR28 -> 0
A29: 127-41-3 | B29: alpha-Ionon Halal Kosher | C29: ='Übersicht Score Index'!C29*Rezepte!AP29 -> 0 | D29: ='Übersicht Score Index'!C29*Rezepte!AQ29 -> 0 | E29: ='Übersicht Score Index'!C29*Rezepte!AR29 -> 0 | F29: ='Übersicht Score Index'!D29*Rezepte!AP29 -> 0 | G29: ='Übersicht Score Index'!D29*Rezepte!AQ29 -> 0 | H29: ='Übersicht Score Index'!D29*Rezepte!AR29 -> 0 | I29: ='Übersicht Score Index'!E29*Rezepte!AP29 -> 0 | J29: ='Übersicht Score Index'!E29*Rezepte!AQ29 -> 0 | K29: ='Übersicht Score Index'!E29*Rezepte!AR29 -> 0 | L29: ='Übersicht Score Index'!F29*Rezepte!AP29 -> 0 | M29: ='Übersicht Score Index'!F29*Rezepte!AQ29 -> 0 | N29: ='Übersicht Score Index'!F29*Rezepte!AR29 -> 0 | O29: ='Übersicht Score Index'!G29*Rezepte!AP29 -> 0 | P29: ='Übersicht Score Index'!G29*Rezepte!AQ29 -> 0 | Q29: ='Übersicht Score Index'!G29*Rezepte!AR29 -> 0 | R29: ='Übersicht Score Index'!H29*Rezepte!AP29 -> 0 | S29: ='Übersicht Score Index'!H29*Rezepte!AQ29 -> 0 | T29: ='Übersicht Score Index'!H29*Rezepte!AR29 -> 0 | U29: ='Übersicht Score Index'!I29*Rezepte!AP29 -> 0 | V29: ='Übersicht Score Index'!I29*Rezepte!AQ29 -> 0 | W29: ='Übersicht Score Index'!I29*Rezepte!AR29 -> 0
A30: 79-69-6 | B30: alpha-Iron | C30: ='Übersicht Score Index'!C30*Rezepte!AP30 -> 0 | D30: ='Übersicht Score Index'!C30*Rezepte!AQ30 -> 0 | E30: ='Übersicht Score Index'!C30*Rezepte!AR30 -> 0 | F30: ='Übersicht Score Index'!D30*Rezepte!AP30 -> 0 | G30: ='Übersicht Score Index'!D30*Rezepte!AQ30 -> 0 | H30: ='Übersicht Score Index'!D30*Rezepte!AR30 -> 0 | I30: ='Übersicht Score Index'!E30*Rezepte!AP30 -> 0 | J30: ='Übersicht Score Index'!E30*Rezepte!AQ30 -> 0 | K30: ='Übersicht Score Index'!E30*Rezepte!AR30 -> 0 | L30: ='Übersicht Score Index'!F30*Rezepte!AP30 -> 0 | M30: ='Übersicht Score Index'!F30*Rezepte!AQ30 -> 0 | N30: ='Übersicht Score Index'!F30*Rezepte!AR30 -> 0 | O30: ='Übersicht Score Index'!G30*Rezepte!AP30 -> 0 | P30: ='Übersicht Score Index'!G30*Rezepte!AQ30 -> 0 | Q30: ='Übersicht Score Index'!G30*Rezepte!AR30 -> 0 | R30: ='Übersicht Score Index'!H30*Rezepte!AP30 -> 0 | S30: ='Übersicht Score Index'!H30*Rezepte!AQ30 -> 0 | T30: ='Übersicht Score Index'!H30*Rezepte!AR30 -> 0 | U30: ='Übersicht Score Index'!I30*Rezepte!AP30 -> 0 | V30: ='Übersicht Score Index'!I30*Rezepte!AQ30 -> 0 | W30: ='Übersicht Score Index'!I30*Rezepte!AR30 -> 0
A31: 98-55-5 | B31: alpha-Terpineol Kosher Halal | C31: ='Übersicht Score Index'!C31*Rezepte!AP31 -> 0 | D31: ='Übersicht Score Index'!C31*Rezepte!AQ31 -> 0 | E31: ='Übersicht Score Index'!C31*Rezepte!AR31 -> 0 | F31: ='Übersicht Score Index'!D31*Rezepte!AP31 -> 0 | G31: ='Übersicht Score Index'!D31*Rezepte!AQ31 -> 0 | H31: ='Übersicht Score Index'!D31*Rezepte!AR31 -> 0 | I31: ='Übersicht Score Index'!E31*Rezepte!AP31 -> 0 | J31: ='Übersicht Score Index'!E31*Rezepte!AQ31 -> 0 | K31: ='Übersicht Score Index'!E31*Rezepte!AR31 -> 0 | L31: ='Übersicht Score Index'!F31*Rezepte!AP31 -> 0 | M31: ='Übersicht Score Index'!F31*Rezepte!AQ31 -> 0 | N31: ='Übersicht Score Index'!F31*Rezepte!AR31 -> 0 | O31: ='Übersicht Score Index'!G31*Rezepte!AP31 -> 0 | P31: ='Übersicht Score Index'!G31*Rezepte!AQ31 -> 0 | Q31: ='Übersicht Score Index'!G31*Rezepte!AR31 -> 0 | R31: ='Übersicht Score Index'!H31*Rezepte!AP31 -> 0 | S31: ='Übersicht Score Index'!H31*Rezepte!AQ31 -> 0 | T31: ='Übersicht Score Index'!H31*Rezepte!AR31 -> 0 | U31: ='Übersicht Score Index'!I31*Rezepte!AP31 -> 0 | V31: ='Übersicht Score Index'!I31*Rezepte!AQ31 -> 0 | W31: ='Übersicht Score Index'!I31*Rezepte!AR31 -> 0
